Workbook

Sheet Projections
A1: INR Mn | B1: Unit | C1: Source / Driver | D1: 1Q22 | E1: 2Q22 | F1: 3Q22 | G1: 4Q22 | H1: 1Q23 | I1: 2Q23 | J1: 3Q23 | K1: 4Q23 | L1: 1Q24 | M1: 2Q24 | N1: 3Q24 | O1: 4Q24 | P1: 1Q25 | Q1: 2Q25 | R1: 3Q25 | S1: 4Q25 | T1: 1Q26 | U1: 2Q26 | V1: 3Q26 | W1: 4Q26 | X1: 1Q27 | Y1: 2Q27 | Z1: 3Q27 | AA1: 4Q27 | AC1: FY19 | AD1: FY20 | AE1: FY21 | AF1: FY22 | AG1: FY23 | AH1: FY24 | AI1: FY25 | AJ1: FY26 | AK1: FY27E | AL1: FY28E | AM1: FY29E | AN1: FY30E
A2: Fiscal Year End | D2: =DATE(2021,6,30) | E2: =EOMONTH(D2,-3) | F2: =EOMONTH(E2,-3) | G2: =EOMONTH(F2,-3) | H2: =EOMONTH(G2,-3) | I2: =EOMONTH(H2,-3) | J2: =EOMONTH(I2,-3) | K2: =EOMONTH(J2,-3) | L2: =EOMONTH(K2,-3) | ... AA2: =EOMONTH(Z2,-3) | AC2: =DATE(2019,3,31) | AD2: =DATE(2020,3,31) | AE2: =DATE(2021,3,31) | AF2: =DATE(2022,3,31) | AG2: =DATE(2023,3,31) | AH2: =DATE(2024,3,31) | AI2: =DATE(2025,3,31) | AJ2: =DATE(2026,3,31) | AK2: =DATE(2027,3,31) | AL2: =DATE(2028,3,31) | AM2: =DATE(2029,3,31) | AN2: =DATE(2030,3,31)
A3: All figures in INR Mn unless stated otherwise. Historical quarters (1Q22-4Q26) and historical annual columns (FY19-FY26) link to the Raw Data tabs. 1Q27-4Q27 are left blank for a later quarterly-projection pass. FY27E-FY30E are annual projections, each chained off the preceding column in this sheet: red (#A20000) cells are hardcoded assumptions -- edit these to change the forecast; black cells are formulas.
A4: SUMMARY
A5: Total GMV | B5: Rs Mn | C5: Formula | D5: =IFERROR(D32+D61+D84,"") | E5: =IFERROR(E32+E61+E84,"") | F5: =IFERROR(F32+F61+F84,"") | G5: =IFERROR(G32+G61+G84,"") | H5: =IFERROR(H32+H61+H84,"") | I5: =IFERROR(I32+I61+I84,"") | J5: =IFERROR(J32+J61+J84,"") | K5: =IFERROR(K32+K61+K84,"") | ... W5: =IFERROR(W32+W61+W84,"") | AC5: =IFERROR(AC32+AC61+AC84,"") | AD5: =IFERROR(AD32+AD61+AD84,"") | AE5: =IFERROR(AE32+AE61+AE84,"") | AF5: =IFERROR(AF32+AF61+AF84,"") | AG5: =IFERROR(AG32+AG61+AG84,"") | AH5: =IFERROR(AH32+AH61+AH84,"") | AI5: =IFERROR(AI32+AI61+AI84,"") | AJ5: =IFERROR(AJ32+AJ61+AJ84,"") | ... AN5: =IFERROR(AN32+AN61+AN84,"")
A6: YoY growth | B6: % | C6: Formula | H6: =IFERROR(H5/D5-1,"") | I6: =IFERROR(I5/E5-1,"") | J6: =IFERROR(J5/F5-1,"") | K6: =IFERROR(K5/G5-1,"") | L6: =IFERROR(L5/H5-1,"") | M6: =IFERROR(M5/I5-1,"") | N6: =IFERROR(N5/J5-1,"") | O6: =IFERROR(O5/K5-1,"") | ... W6: =IFERROR(W5/S5-1,"") | AD6: =IFERROR(AD5/AC5-1,"") | AE6: =IFERROR(AE5/AD5-1,"") | AF6: =IFERROR(AF5/AE5-1,"") | AG6: =IFERROR(AG5/AF5-1,"") | AH6: =IFERROR(AH5/AG5-1,"") | AI6: =IFERROR(AI5/AH5-1,"") | AJ6: =IFERROR(AJ5/AI5-1,"") | AK6: =IFERROR(AK5/AJ5-1,"") | ... AN6: =IFERROR(AN5/AM5-1,"")
A7: Total NSV | B7: Rs Mn | C7: Formula | D7: =IFERROR(D35+D64+D87,"") | E7: =IFERROR(E35+E64+E87,"") | F7: =IFERROR(F35+F64+F87,"") | G7: =IFERROR(G35+G64+G87,"") | H7: =IFERROR(H35+H64+H87,"") | I7: =IFERROR(I35+I64+I87,"") | J7: =IFERROR(J35+J64+J87,"") | K7: =IFERROR(K35+K64+K87,"") | ... W7: =IFERROR(W35+W64+W87,"") | AC7: =IFERROR(AC35+AC64+AC87,"") | AD7: =IFERROR(AD35+AD64+AD87,"") | AE7: =IFERROR(AE35+AE64+AE87,"") | AF7: =IFERROR(AF35+AF64+AF87,"") | AG7: =IFERROR(AG35+AG64+AG87,"") | AH7: =IFERROR(AH35+AH64+AH87,"") | AI7: =IFERROR(AI35+AI64+AI87,"") | AJ7: =IFERROR(AJ35+AJ64+AJ87,"") | ... AN7: =IFERROR(AN35+AN64+AN87,"")
A8: NSV / GMV | B8: % | C8: Formula | D8: =IFERROR(D7/D5,"") | E8: =IFERROR(E7/E5,"") | F8: =IFERROR(F7/F5,"") | G8: =IFERROR(G7/G5,"") | H8: =IFERROR(H7/H5,"") | I8: =IFERROR(I7/I5,"") | J8: =IFERROR(J7/J5,"") | K8: =IFERROR(K7/K5,"") | ... W8: =IFERROR(W7/W5,"") | AC8: =IFERROR(AC7/AC5,"") | AD8: =IFERROR(AD7/AD5,"") | AE8: =IFERROR(AE7/AE5,"") | AF8: =IFERROR(AF7/AF5,"") | AG8: =IFERROR(AG7/AG5,"") | AH8: =IFERROR(AH7/AH5,"") | AI8: =IFERROR(AI7/AI5,"") | AJ8: =IFERROR(AJ7/AJ5,"")
A9: Total Revenue | B9: Rs Mn | C9: Formula | D9: =IFERROR(D37+D66+D89,"") | E9: =IFERROR(E37+E66+E89,"") | F9: =IFERROR(F37+F66+F89,"") | G9: =IFERROR(G37+G66+G89,"") | H9: =IFERROR(H37+H66+H89,"") | I9: =IFERROR(I37+I66+I89,"") | J9: =IFERROR(J37+J66+J89,"") | K9: =IFERROR(K37+K66+K89,"") | ... W9: =IFERROR(W37+W66+W89,"") | AC9: =IFERROR(AC37+AC66+AC89,"") | AD9: =IFERROR(AD37+AD66+AD89,"") | AE9: =IFERROR(AE37+AE66+AE89,"") | AF9: =IFERROR(AF37+AF66+AF89,"") | AG9: =IFERROR(AG37+AG66+AG89,"") | AH9: =IFERROR(AH37+AH66+AH89,"") | AI9: =IFERROR(AI37+AI66+AI89,"") | AJ9: =IFERROR(AJ37+AJ66+AJ89,"") | ... AN9: =IFERROR(AN37+AN66+AN89,"")
A10: YoY growth | B10: % | C10: Formula | H10: =IFERROR(H9/D9-1,"") | I10: =IFERROR(I9/E9-1,"") | J10: =IFERROR(J9/F9-1,"") | K10: =IFERROR(K9/G9-1,"") | L10: =IFERROR(L9/H9-1,"") | M10: =IFERROR(M9/I9-1,"") | N10: =IFERROR(N9/J9-1,"") | O10: =IFERROR(O9/K9-1,"") | ... W10: =IFERROR(W9/S9-1,"") | AD10: =IFERROR(AD9/AC9-1,"") | AE10: =IFERROR(AE9/AD9-1,"") | AF10: =IFERROR(AF9/AE9-1,"") | AG10: =IFERROR(AG9/AF9-1,"") | AH10: =IFERROR(AH9/AG9-1,"") | AI10: =IFERROR(AI9/AH9-1,"") | AJ10: =IFERROR(AJ9/AI9-1,"") | AK10: =IFERROR(AK9/AJ9-1,"") | ... AN10: =IFERROR(AN9/AM9-1,"")
A11: Gross Profit | B11: Rs Mn | C11: Formula | D11: =IFERROR(D39+D68+D91,"") | E11: =IFERROR(E39+E68+E91,"") | F11: =IFERROR(F39+F68+F91,"") | G11: =IFERROR(G39+G68+G91,"") | H11: =IFERROR(H39+H68+H91,"") | I11: =IFERROR(I39+I68+I91,"") | J11: =IFERROR(J39+J68+J91,"") | K11: =IFERROR(K39+K68+K91,"") | ... W11: =IFERROR(W39+W68+W91,"") | AC11: =IFERROR(AC39+AC68+AC91,"") | AD11: =IFERROR(AD39+AD68+AD91,"") | AE11: =IFERROR(AE39+AE68+AE91,"") | AF11: =IFERROR(AF39+AF68+AF91,"") | AG11: =IFERROR(AG39+AG68+AG91,"") | AH11: =IFERROR(AH39+AH68+AH91,"") | AI11: =IFERROR(AI39+AI68+AI91,"") | AJ11: =IFERROR(AJ39+AJ68+AJ91,"") | ... AN11: =IFERROR(AN39+AN68+AN91,"")
A12: Gross margin (% of NSV) | B12: % | C12: Formula | D12: =IFERROR(D11/D7,"") | E12: =IFERROR(E11/E7,"") | F12: =IFERROR(F11/F7,"") | G12: =IFERROR(G11/G7,"") | H12: =IFERROR(H11/H7,"") | I12: =IFERROR(I11/I7,"") | J12: =IFERROR(J11/J7,"") | K12: =IFERROR(K11/K7,"") | ... W12: =IFERROR(W11/W7,"") | AC12: =IFERROR(AC11/AC7,"") | AD12: =IFERROR(AD11/AD7,"") | AE12: =IFERROR(AE11/AE7,"") | AF12: =IFERROR(AF11/AF7,"") | AG12: =IFERROR(AG11/AG7,"") | AH12: =IFERROR(AH11/AH7,"") | AI12: =IFERROR(AI11/AI7,"") | AJ12: =IFERROR(AJ11/AJ7,"")
A13: EBITDA | B13: Rs Mn | C13: Formula | D13: =D99 | E13: =E99 | F13: =F99 | G13: =G99 | H13: =H99 | I13: =I99 | J13: =J99 | K13: =K99 | ... W13: =W99 | AC13: =AC99 | AD13: =AD99 | AE13: =AE99 | AF13: =AF99 | AG13: =AG99 | AH13: =AH99 | AI13: =AI99 | AJ13: =AJ99 | ... AN13: =AN99
A14: EBITDA margin (% of NSV) | B14: % | C14: Formula | D14: =IFERROR(D13/D7,"") | E14: =IFERROR(E13/E7,"") | F14: =IFERROR(F13/F7,"") | G14: =IFERROR(G13/G7,"") | H14: =IFERROR(H13/H7,"") | I14: =IFERROR(I13/I7,"") | J14: =IFERROR(J13/J7,"") | K14: =IFERROR(K13/K7,"") | ... W14: =IFERROR(W13/W7,"") | AC14: =IFERROR(AC13/AC7,"") | AD14: =IFERROR(AD13/AD7,"") | AE14: =IFERROR(AE13/AE7,"") | AF14: =IFERROR(AF13/AF7,"") | AG14: =IFERROR(AG13/AG7,"") | AH14: =IFERROR(AH13/AH7,"") | AI14: =IFERROR(AI13/AI7,"") | AJ14: =IFERROR(AJ13/AJ7,"")
A15: PAT | B15: Rs Mn | C15: Formula | D15: =D111 | E15: =E111 | F15: =F111 | G15: =G111 | H15: =H111 | I15: =I111 | J15: =J111 | K15: =K111 | ... W15: =W111 | AC15: =AC111 | AD15: =AD111 | AE15: =AE111 | AF15: =AF111 | AG15: =AG111 | AH15: =AH111 | AI15: =AI111 | AJ15: =AJ111 | ... AN15: =AN111
A16: PAT margin (% of Revenue) | B16: % | C16: Formula | D16: =IFERROR(D15/D9,"") | E16: =IFERROR(E15/E9,"") | F16: =IFERROR(F15/F9,"") | G16: =IFERROR(G15/G9,"") | H16: =IFERROR(H15/H9,"") | I16: =IFERROR(I15/I9,"") | J16: =IFERROR(J15/J9,"") | K16: =IFERROR(K15/K9,"") | ... W16: =IFERROR(W15/W9,"") | AC16: =IFERROR(AC15/AC9,"") | AD16: =IFERROR(AD15/AD9,"") | AE16: =IFERROR(AE15/AE9,"") | AF16: =IFERROR(AF15/AF9,"") | AG16: =IFERROR(AG15/AG9,"") | AH16: =IFERROR(AH15/AH9,"") | AI16: =IFERROR(AI15/AI9,"") | AJ16: =IFERROR(AJ15/AJ9,"")
A17: EPS (diluted) | B17: Rs | C17: Formula | D17: =D114 | E17: =E114 | F17: =F114 | G17: =G114 | H17: =H114 | I17: =I114 | J17: =J114 | K17: =K114 | ... W17: =W114 | AC17: =AC114 | AD17: =AD114 | AE17: =AE114 | AF17: =AF114 | AG17: =AG114 | AH17: =AH114 | AI17: =AI114 | AJ17: =AJ114 | ... AN17: =AN114
A19: Segment mix (% of Total GMV)
A20: Beauty | B20: % | C20: Formula | D20: =IFERROR(D32/D5,"") | E20: =IFERROR(E32/E5,"") | F20: =IFERROR(F32/F5,"") | G20: =IFERROR(G32/G5,"") | H20: =IFERROR(H32/H5,"") | I20: =IFERROR(I32/I5,"") | J20: =IFERROR(J32/J5,"") | K20: =IFERROR(K32/K5,"") | ... W20: =IFERROR(W32/W5,"") | AC20: =IFERROR(AC32/AC5,"") | AD20: =IFERROR(AD32/AD5,"") | AE20: =IFERROR(AE32/AE5,"") | AF20: =IFERROR(AF32/AF5,"") | AG20: =IFERROR(AG32/AG5,"") | AH20: =IFERROR(AH32/AH5,"") | AI20: =IFERROR(AI32/AI5,"") | AJ20: =IFERROR(AJ32/AJ5,"") | ... AN20: =IFERROR(AN32/AN5,"")
A21: Fashion | B21: % | C21: Formula | D21: =IFERROR(D61/D5,"") | E21: =IFERROR(E61/E5,"") | F21: =IFERROR(F61/F5,"") | G21: =IFERROR(G61/G5,"") | H21: =IFERROR(H61/H5,"") | I21: =IFERROR(I61/I5,"") | J21: =IFERROR(J61/J5,"") | K21: =IFERROR(K61/K5,"") | ... W21: =IFERROR(W61/W5,"") | AC21: =IFERROR(AC61/AC5,"") | AD21: =IFERROR(AD61/AD5,"") | AE21: =IFERROR(AE61/AE5,"") | AF21: =IFERROR(AF61/AF5,"") | AG21: =IFERROR(AG61/AG5,"") | AH21: =IFERROR(AH61/AH5,"") | AI21: =IFERROR(AI61/AI5,"") | AJ21: =IFERROR(AJ61/AJ5,"") | ... AN21: =IFERROR(AN61/AN5,"")
A22: New Business | B22: % | C22: Formula | D22: =IFERROR(D84/D5,"") | E22: =IFERROR(E84/E5,"") | F22: =IFERROR(F84/F5,"") | G22: =IFERROR(G84/G5,"") | H22: =IFERROR(H84/H5,"") | I22: =IFERROR(I84/I5,"") | J22: =IFERROR(J84/J5,"") | K22: =IFERROR(K84/K5,"") | ... W22: =IFERROR(W84/W5,"") | AC22: =IFERROR(AC84/AC5,"") | AD22: =IFERROR(AD84/AD5,"") | AE22: =IFERROR(AE84/AE5,"") | AF22: =IFERROR(AF84/AF5,"") | AG22: =IFERROR(AG84/AG5,"") | AH22: =IFERROR(AH84/AH5,"") | AI22: =IFERROR(AI84/AI5,"") | AJ22: =IFERROR(AJ84/AJ5,"") | ... AN22: =IFERROR(AN84/AN5,"")
A24: BEAUTY (incl. SuperStore)
A25: Definition: BPC (online + offline) + Superstore by Nykaa + Nykaa Man Grooming + House of Nykaa owned brands. NOTE: AUTC/Orders/AOV here are sourced from the deck's 'BPC Vertical' KPI table, which is a narrower scope than the GMV/NSV/Revenue lines below (GMV includes SuperStore, BPC Vertical orders don't) -- see the equivalent caveat on the Raw Data - Ops KPIs tab. AOV = GMV/Orders here is therefore a blended incl-SuperStore figure, not Nykaa's own reported BPC AOV.
A26: Annual transacting customers (AUTC) | B26: mn | C26: Link: Raw Data - Ops KPIs | D26: ='Raw Data - Ops KPIs'!D35 | E26: ='Raw Data - Ops KPIs'!E35 | F26: ='Raw Data - Ops KPIs'!F35 | G26: ='Raw Data - Ops KPIs'!G35 | H26: ='Raw Data - Ops KPIs'!H35 | I26: ='Raw Data - Ops KPIs'!I35 | J26: ='Raw Data - Ops KPIs'!J35 | K26: ='Raw Data - Ops KPIs'!K35 | ... W26: ='Raw Data - Ops KPIs'!W35 | AF26: ='Raw Data - Ops KPIs'!AF35 | AG26: ='Raw Data - Ops KPIs'!AG35 | AH26: ='Raw Data - Ops KPIs'!AH35 | AI26: ='Raw Data - Ops KPIs'!AI35 | AJ26: ='Raw Data - Ops KPIs'!AJ35 | AK26: =AJ26*(1+AK27) | AL26: =AK26*(1+AL27) | AM26: =AL26*(1+AM27) | AN26: =AM26*(1+AN27)
A27: YoY growth | B27: % | C27: Assumption (edit me) | H27: =IFERROR(H26/D26-1,"") | I27: =IFERROR(I26/E26-1,"") | J27: =IFERROR(J26/F26-1,"") | K27: =IFERROR(K26/G26-1,"") | L27: =IFERROR(L26/H26-1,"") | M27: =IFERROR(M26/I26-1,"") | N27: =IFERROR(N26/J26-1,"") | O27: =IFERROR(O26/K26-1,"") | ... W27: =IFERROR(W26/S26-1,"") | AD27: =IFERROR(AD26/AC26-1,"") | AE27: =IFERROR(AE26/AD26-1,"") | AF27: =IFERROR(AF26/AE26-1,"") | AG27: =IFERROR(AG26/AF26-1,"") | AH27: =IFERROR(AH26/AG26-1,"") | AI27: =IFERROR(AI26/AH26-1,"") | AJ27: =IFERROR(AJ26/AI26-1,"") | AK27: 0.247 | AL27: 0.247 | AM27: 0.247 | AN27: 0.247
A28: Average order frequency | B28: x | C28: Assumption (edit me) | D28: =IFERROR(D29/D26,"") | E28: =IFERROR(E29/E26,"") | F28: =IFERROR(F29/F26,"") | G28: =IFERROR(G29/G26,"") | H28: =IFERROR(H29/H26,"") | I28: =IFERROR(I29/I26,"") | J28: =IFERROR(J29/J26,"") | K28: =IFERROR(K29/K26,"") | ... W28: =IFERROR(W29/W26,"") | AC28: =IFERROR(AC29/AC26,"") | AD28: =IFERROR(AD29/AD26,"") | AE28: =IFERROR(AE29/AE26,"") | AF28: =IFERROR(AF29/AF26,"") | AG28: =IFERROR(AG29/AG26,"") | AH28: =IFERROR(AH29/AH26,"") | AI28: =IFERROR(AI29/AI26,"") | AJ28: =IFERROR(AJ29/AJ26,"") | AK28: 3.34 | AL28: 3.34 | AM28: 3.34 | AN28: 3.34
A29: Number of orders | B29: mn | C29: Link: Raw Data - Ops KPIs | D29: ='Raw Data - Ops KPIs'!D37 | E29: ='Raw Data - Ops KPIs'!E37 | F29: ='Raw Data - Ops KPIs'!F37 | G29: ='Raw Data - Ops KPIs'!G37 | H29: ='Raw Data - Ops KPIs'!H37 | I29: ='Raw Data - Ops KPIs'!I37 | J29: ='Raw Data - Ops KPIs'!J37 | K29: ='Raw Data - Ops KPIs'!K37 | ... W29: ='Raw Data - Ops KPIs'!W37 | AF29: ='Raw Data - Ops KPIs'!AF37 | AG29: ='Raw Data - Ops KPIs'!AG37 | AH29: ='Raw Data - Ops KPIs'!AH37 | AI29: ='Raw Data - Ops KPIs'!AI37 | AJ29: ='Raw Data - Ops KPIs'!AJ37 | AK29: =AK26*AK28 | AL29: =AL26*AL28 | AM29: =AM26*AM28 | AN29: =AN26*AN28
A30: Average order value | B30: Rs | C30: Formula | D30: =IFERROR(D32/D29,"") | E30: =IFERROR(E32/E29,"") | F30: =IFERROR(F32/F29,"") | G30: =IFERROR(G32/G29,"") | H30: =IFERROR(H32/H29,"") | I30: =IFERROR(I32/I29,"") | J30: =IFERROR(J32/J29,"") | K30: =IFERROR(K32/K29,"") | ... W30: =IFERROR(W32/W29,"") | AC30: =IFERROR(AC32/AC29,"") | AD30: =IFERROR(AD32/AD29,"") | AE30: =IFERROR(AE32/AE29,"") | AF30: =IFERROR(AF32/AF29,"") | AG30: =IFERROR(AG32/AG29,"") | AH30: =IFERROR(AH32/AH29,"") | AI30: =IFERROR(AI32/AI29,"") | AJ30: =IFERROR(AJ32/AJ29,"") | AK30: =AJ30*(1+AK31) | AL30: =AK30*(1+AL31) | AM30: =AL30*(1+AM31) | AN30: =AM30*(1+AN31)
A31: YoY growth | B31: % | C31: Assumption (edit me) | AK31: 0.052 | AL31: 0.052 | AM31: 0.052 | AN31: 0.052
A32: GMV | B32: Rs Mn | C32: Link: Raw Data - Ops KPIs | D32: ='Raw Data - Ops KPIs'!D39 | E32: ='Raw Data - Ops KPIs'!E39 | F32: ='Raw Data - Ops KPIs'!F39 | G32: ='Raw Data - Ops KPIs'!G39 | H32: ='Raw Data - Ops KPIs'!H39 | I32: ='Raw Data - Ops KPIs'!I39 | J32: ='Raw Data - Ops KPIs'!J39 | K32: ='Raw Data - Ops KPIs'!K39 | ... W32: ='Raw Data - Ops KPIs'!W39 | AF32: ='Raw Data - Ops KPIs'!AF39 | AG32: ='Raw Data - Ops KPIs'!AG39 | AH32: ='Raw Data - Ops KPIs'!AH39 | AI32: ='Raw Data - Ops KPIs'!AI39 | AJ32: ='Raw Data - Ops KPIs'!AJ39 | AK32: =AK29*AK30 | AL32: =AL29*AL30 | AM32: =AM29*AM30 | AN32: =AN29*AN30
A33: YoY growth | B33: % | C33: Formula | H33: =IFERROR(H32/D32-1,"") | I33: =IFERROR(I32/E32-1,"") | J33: =IFERROR(J32/F32-1,"") | K33: =IFERROR(K32/G32-1,"") | L33: =IFERROR(L32/H32-1,"") | M33: =IFERROR(M32/I32-1,"") | N33: =IFERROR(N32/J32-1,"") | O33: =IFERROR(O32/K32-1,"") | ... W33: =IFERROR(W32/S32-1,"") | AD33: =IFERROR(AD32/AC32-1,"") | AE33: =IFERROR(AE32/AD32-1,"") | AF33: =IFERROR(AF32/AE32-1,"") | AG33: =IFERROR(AG32/AF32-1,"") | AH33: =IFERROR(AH32/AG32-1,"") | AI33: =IFERROR(AI32/AH32-1,"") | AJ33: =IFERROR(AJ32/AI32-1,"") | AK33: =IFERROR(AK32/AJ32-1,"") | ... AN33: =IFERROR(AN32/AM32-1,"")
A34: NSV / GMV | B34: % | C34: Assumption (edit me) | D34: =IFERROR(D35/D32,"") | E34: =IFERROR(E35/E32,"") | F34: =IFERROR(F35/F32,"") | G34: =IFERROR(G35/G32,"") | H34: =IFERROR(H35/H32,"") | I34: =IFERROR(I35/I32,"") | J34: =IFERROR(J35/J32,"") | K34: =IFERROR(K35/K32,"") | ... W34: =IFERROR(W35/W32,"") | AC34: =IFERROR(AC35/AC32,"") | AD34: =IFERROR(AD35/AD32,"") | AE34: =IFERROR(AE35/AE32,"") | AF34: =IFERROR(AF35/AF32,"") | AG34: =IFERROR(AG35/AG32,"") | AH34: =IFERROR(AH35/AH32,"") | AI34: =IFERROR(AI35/AI32,"") | AJ34: =IFERROR(AJ35/AJ32,"") | AK34: 0.569 | AL34: 0.569 | AM34: 0.569 | AN34: 0.569
A35: NSV | B35: Rs Mn | C35: Link: Raw Data - Ops KPIs | D35: ='Raw Data - Ops KPIs'!D42 | E35: ='Raw Data - Ops KPIs'!E42 | F35: ='Raw Data - Ops KPIs'!F42 | G35: ='Raw Data - Ops KPIs'!G42 | H35: ='Raw Data - Ops KPIs'!H42 | I35: ='Raw Data - Ops KPIs'!I42 | J35: ='Raw Data - Ops KPIs'!J42 | K35: ='Raw Data - Ops KPIs'!K42 | ... W35: ='Raw Data - Ops KPIs'!W42 | AF35: ='Raw Data - Ops KPIs'!AF42 | AG35: ='Raw Data - Ops KPIs'!AG42 | AH35: ='Raw Data - Ops KPIs'!AH42 | AI35: ='Raw Data - Ops KPIs'!AI42 | AJ35: ='Raw Data - Ops KPIs'!AJ42 | AK35: =AK32*AK34 | AL35: =AL32*AL34 | AM35: =AM32*AM34 | AN35: =AN32*AN34
A36: Revenue / NSV | B36: % | C36: Assumption (edit me) | D36: =IFERROR(D37/D35,"") | E36: =IFERROR(E37/E35,"") | F36: =IFERROR(F37/F35,"") | G36: =IFERROR(G37/G35,"") | H36: =IFERROR(H37/H35,"") | I36: =IFERROR(I37/I35,"") | J36: =IFERROR(J37/J35,"") | K36: =IFERROR(K37/K35,"") | ... W36: =IFERROR(W37/W35,"") | AC36: =IFERROR(AC37/AC35,"") | AD36: =IFERROR(AD37/AD35,"") | AE36: =IFERROR(AE37/AE35,"") | AF36: =IFERROR(AF37/AF35,"") | AG36: =IFERROR(AG37/AG35,"") | AH36: =IFERROR(AH37/AH35,"") | AI36: =IFERROR(AI37/AI35,"") | AJ36: =IFERROR(AJ37/AJ35,"") | AK36: 1.075 | AL36: 1.075 | AM36: 1.075 | AN36: 1.075
A37: Revenue | B37: Rs Mn | C37: Link: Raw Data - Ops KPIs | D37: ='Raw Data - Ops KPIs'!D44 | E37: ='Raw Data - Ops KPIs'!E44 | F37: ='Raw Data - Ops KPIs'!F44 | G37: ='Raw Data - Ops KPIs'!G44 | H37: ='Raw Data - Ops KPIs'!H44 | I37: ='Raw Data - Ops KPIs'!I44 | J37: ='Raw Data - Ops KPIs'!J44 | K37: ='Raw Data - Ops KPIs'!K44 | ... W37: ='Raw Data - Ops KPIs'!W44 | AF37: ='Raw Data - Ops KPIs'!AF44 | AG37: ='Raw Data - Ops KPIs'!AG44 | AH37: ='Raw Data - Ops KPIs'!AH44 | AI37: ='Raw Data - Ops KPIs'!AI44 | AJ37: ='Raw Data - Ops KPIs'!AJ44 | AK37: =AK35*AK36 | AL37: =AL35*AL36 | AM37: =AM35*AM36 | AN37: =AN35*AN36
A38: Gross margin (% of NSV) | B38: % | C38: Assumption (edit me) | D38: =IFERROR(D39/D35,"") | E38: =IFERROR(E39/E35,"") | F38: =IFERROR(F39/F35,"") | G38: =IFERROR(G39/G35,"") | H38: =IFERROR(H39/H35,"") | I38: =IFERROR(I39/I35,"") | J38: =IFERROR(J39/J35,"") | K38: =IFERROR(K39/K35,"") | ... W38: =IFERROR(W39/W35,"") | AC38: =IFERROR(AC39/AC35,"") | AD38: =IFERROR(AD39/AD35,"") | AE38: =IFERROR(AE39/AE35,"") | AF38: =IFERROR(AF39/AF35,"") | AG38: =IFERROR(AG39/AG35,"") | AH38: =IFERROR(AH39/AH35,"") | AI38: =IFERROR(AI39/AI35,"") | AJ38: =IFERROR(AJ39/AJ35,"") | AK38: 0.447 | AL38: 0.447 | AM38: 0.447 | AN38: 0.447
A39: Gross profit | B39: Rs Mn | C39: Link: Raw Data - Ops KPIs | D39: ='Raw Data - Ops KPIs'!D46 | E39: ='Raw Data - Ops KPIs'!E46 | F39: ='Raw Data - Ops KPIs'!F46 | G39: ='Raw Data - Ops KPIs'!G46 | H39: ='Raw Data - Ops KPIs'!H46 | I39: ='Raw Data - Ops KPIs'!I46 | J39: ='Raw Data - Ops KPIs'!J46 | K39: ='Raw Data - Ops KPIs'!K46 | ... W39: ='Raw Data - Ops KPIs'!W46 | AF39: ='Raw Data - Ops KPIs'!AF46 | AG39: ='Raw Data - Ops KPIs'!AG46 | AH39: ='Raw Data - Ops KPIs'!AH46 | AI39: ='Raw Data - Ops KPIs'!AI46 | AJ39: ='Raw Data - Ops KPIs'!AJ46 | AK39: =AK35*AK38 | AL39: =AL35*AL38 | AM39: =AM35*AM38 | AN39: =AN35*AN38
A40: Fulfilment (% of NSV) | B40: % | C40: Assumption (edit me) | D40: =IFERROR(D41/D35,"") | E40: =IFERROR(E41/E35,"") | F40: =IFERROR(F41/F35,"") | G40: =IFERROR(G41/G35,"") | H40: =IFERROR(H41/H35,"") | I40: =IFERROR(I41/I35,"") | J40: =IFERROR(J41/J35,"") | K40: =IFERROR(K41/K35,"") | ... W40: =IFERROR(W41/W35,"") | AC40: =IFERROR(AC41/AC35,"") | AD40: =IFERROR(AD41/AD35,"") | AE40: =IFERROR(AE41/AE35,"") | AF40: =IFERROR(AF41/AF35,"") | AG40: =IFERROR(AG41/AG35,"") | AH40: =IFERROR(AH41/AH35,"") | AI40: =IFERROR(AI41/AI35,"") | AJ40: =IFERROR(AJ41/AJ35,"") | AK40: 0.093 | AL40: 0.093 | AM40: 0.093 | AN40: 0.093
A41: Fulfilment cost | B41: Rs Mn | C41: Link: Raw Data - Ops KPIs | D41: ='Raw Data - Ops KPIs'!D48 | E41: ='Raw Data - Ops KPIs'!E48 | F41: ='Raw Data - Ops KPIs'!F48 | G41: ='Raw Data - Ops KPIs'!G48 | H41: ='Raw Data - Ops KPIs'!H48 | I41: ='Raw Data - Ops KPIs'!I48 | J41: ='Raw Data - Ops KPIs'!J48 | K41: ='Raw Data - Ops KPIs'!K48 | ... W41: ='Raw Data - Ops KPIs'!W48 | AF41: ='Raw Data - Ops KPIs'!AF48 | AG41: ='Raw Data - Ops KPIs'!AG48 | AH41: ='Raw Data - Ops KPIs'!AH48 | AI41: ='Raw Data - Ops KPIs'!AI48 | AJ41: ='Raw Data - Ops KPIs'!AJ48 | AK41: =AK35*AK40 | AL41: =AL35*AL40 | AM41: =AM35*AM40 | AN41: =AN35*AN40
A42: o/w Marketing (historical, linked) | B42: Rs Mn | C42: Link: Raw Data - Ops KPIs | D42: ='Raw Data - Ops KPIs'!D49 | E42: ='Raw Data - Ops KPIs'!E49 | F42: ='Raw Data - Ops KPIs'!F49 | G42: ='Raw Data - Ops KPIs'!G49 | H42: ='Raw Data - Ops KPIs'!H49 | I42: ='Raw Data - Ops KPIs'!I49 | J42: ='Raw Data - Ops KPIs'!J49 | K42: ='Raw Data - Ops KPIs'!K49 | ... W42: ='Raw Data - Ops KPIs'!W49 | AF42: ='Raw Data - Ops KPIs'!AF49 | AG42: ='Raw Data - Ops KPIs'!AG49 | AH42: ='Raw Data - Ops KPIs'!AH49 | AI42: ='Raw Data - Ops KPIs'!AI49 | AJ42: ='Raw Data - Ops KPIs'!AJ49
...

Sheet Raw Data - financials
A1: INR Mn | B1: Unit | C1: Source | D1: 1Q22 | E1: 2Q22 | F1: 3Q22 | G1: 4Q22 | H1: 1Q23 | I1: 2Q23 | J1: 3Q23 | K1: 4Q23 | L1: 1Q24 | M1: 2Q24 | N1: 3Q24 | O1: 4Q24 | P1: 1Q25 | Q1: 2Q25 | R1: 3Q25 | S1: 4Q25 | T1: 1Q26 | U1: 2Q26 | V1: 3Q26 | W1: 4Q26 | X1: 1Q27 | Y1: 2Q27 | Z1: 3Q27 | AA1: 4Q27 | AC1: FY19 | AD1: FY20 | AE1: FY21 | AF1: FY22 | AG1: FY23 | AH1: FY24 | AI1: FY25 | AJ1: FY26
A2: Fiscal Year End | D2: =EOMONTH(E2,-3) | E2: =EOMONTH(F2,-3) | F2: =EOMONTH(G2,-3) | G2: =EOMONTH(H2,-3) | H2: =EOMONTH(I2,-3) | I2: =EOMONTH(J2,-3) | J2: =EOMONTH(K2,-3) | K2: =EOMONTH(L2,-3) | ... V2: =EOMONTH(W2,-3) | W2: 46112 | X2: =EOMONTH(W2,3) | Y2: =EOMONTH(X2,3) | Z2: =EOMONTH(Y2,3) | AA2: =EOMONTH(Z2,3) | AC2: 43555 | AD2: 43921 | AE2: 44286 | AF2: 44651 | AG2: 45016 | AH2: 45382 | AI2: 45747 | AJ2: 46112
A3: All figures in INR Mn unless stated otherwise.
A4: PROFIT & LOSS (CONSOLIDATED)
A5: Revenue from operations | B5: INR Mn | C5: Company filings | D5: 8169.91 | E5: 8852.64 | F5: 10983.6 | G5: 9733.2 | H5: 11484.21 | I5: 12308.29 | J5: 14628.26 | K5: 13017.24 | L5: 14218.24 | M5: 15070.24 | N5: 17887.98 | O5: 16679.8 | P5: 17461.1 | Q5: 18747.4 | R5: 22672.1 | S5: 20617.6 | T5: 21549.4 | U5: 23459.8 | V5: 28732.6 | W5: 26481.7 | AC5: 11113.94 | AD5: 17675.33 | AE5: 24408.96 | AF5: 37739.35 | AG5: 51438 | AH5: 63856.26 | AI5: 79498.2 | AJ5: 100223.5
A6: Other income | B6: INR Mn | C6: Company filings | D6: 47.22 | E6: 51.98 | F6: 59.13 | G6: 111.39 | H6: 83.63 | I6: 64.76 | J6: 56.36 | K6: 97.38 | L6: 67.21 | M6: 85.73 | N6: 75.84 | O6: 70.63 | P6: 73.3 | Q6: 54.5 | R6: 55.3 | S6: 89.5 | T6: 93.3 | U6: 80.3 | V6: 62.6 | W6: 91.5 | AC6: 49.88 | AD6: 103.17 | AE6: 117.41 | AF6: 269.72 | AG6: 302.13 | AH6: 299.42 | AI6: 272.6 | AJ6: 327.7
A7: Total Income | B7: INR Mn | D7: =SUM(D5:D6) | E7: =SUM(E5:E6) | F7: =SUM(F5:F6) | G7: =SUM(G5:G6) | H7: =SUM(H5:H6) | I7: =SUM(I5:I6) | J7: =SUM(J5:J6) | K7: =SUM(K5:K6) | ... W7: =SUM(W5:W6) | AC7: =SUM(AC5:AC6) | AD7: =SUM(AD5:AD6) | AE7: =SUM(AE5:AE6) | AF7: =SUM(AF5:AF6) | AG7: =SUM(AG5:AG6) | AH7: =SUM(AH5:AH6) | AI7: =SUM(AI5:AI6) | AJ7: =SUM(AJ5:AJ6)
A9: Expenses
A10: Cost of material consumed | B10: INR Mn | C10: Company filings | D10: 229.37 | E10: 179.32 | F10: 176.56 | G10: 257.87 | H10: 232.97 | I10: 222.51 | J10: 166.08 | K10: 972.77 | L10: 186 | M10: 155.06 | N10: 235.19 | O10: 74.87 | P10: 25.9 | Q10: 14.5 | R10: 27.8 | S10: 12.8 | T10: 33.3 | U10: 3.4 | V10: 22.1 | W10: 87.3 | AC10: 2.41 | AD10: 173.43 | AE10: 382.41 | AF10: 843.12 | AG10: 1594.33 | AH10: 651.13 | AI10: 81 | AJ10: 146.1
A11: Purchase of traded goods | B11: INR Mn | C11: Company filings | D11: 5509.42 | E11: 4848.33 | F11: 6902.15 | G11: 6643.6 | H11: 7415.45 | I11: 5858.02 | J11: 9188.98 | K11: 6017.46 | L11: 9781.98 | M11: 5530.25 | N11: 12322.52 | O11: 10182.01 | P11: 11718 | Q11: 10860.8 | R11: 12849.6 | S11: 11402.3 | T11: 14444.5 | U11: 11965.3 | V11: 15047.7 | W11: 15728.3 | AC11: 7852.43 | AD11: 11787.46 | AE11: 14956.06 | AF11: 24078.31 | AG11: 28479.91 | AH11: 37816.75 | AI11: 46830.8 | AJ11: 57185.8
A12: Changes in inventories of finished goods and stock-in-trade | B12: INR Mn | C12: Company filings | D12: -885.47 | E12: 42.57 | F12: -1182.69 | G12: -1420.88 | H12: -1263 | I12: 650.38 | J12: -1073.5 | K12: 268.69 | L12: -1935.99 | M12: 2888.69 | N12: -2277.21 | O12: -679.51 | P12: -1842.6 | Q12: -338.1 | R12: -116.7 | S12: 112.3 | T12: -2543.5 | U12: 955.7 | V12: 688 | W12: -1366.8 | AC12: -1252.07 | AD12: -1818.84 | AE12: -460.22 | AF12: -3621.28 | AG12: -1417.43 | AH12: -2004.02 | AI12: -2185.2 | AJ12: -2266.6
A13: Employee benefits expense | B13: INR Mn | C13: Company filings | D13: 726.05 | E13: 694.01 | F13: 933.21 | G13: 908 | H13: 1147.09 | I13: 1217.61 | J13: 1279.16 | K13: 1273.31 | L13: 1385.76 | M13: 1363.2 | N13: 1479.3 | O13: 1420.75 | P13: 1558.6 | Q13: 1614.9 | R13: 1746 | S13: 1741.2 | T13: 1820.2 | U13: 1827.7 | V13: 2029 | W13: 2038.4 | AC13: 1172.96 | AD13: 1956.13 | AE13: 2836.47 | AF13: 3259.39 | AG13: 4917.17 | AH13: 5649.01 | AI13: 6660.7 | AJ13: 7715.3
A14: Finance costs | B14: INR Mn | C14: Company filings | D14: 90.14 | E14: 113.49 | F14: 127.9 | G14: 133.58 | H14: 150.63 | I14: 203.56 | J14: 204.25 | K14: 187.61 | L14: 185.48 | M14: 213.09 | N14: 218.41 | O14: 211.34 | P14: 213.1 | Q14: 242.3 | R14: 319.3 | S14: 298.5 | T14: 301.6 | U14: 314.7 | V14: 291.6 | W14: 263.3 | AC14: 263.42 | AD14: 442.93 | AE14: 307.01 | AF14: 465.11 | AG14: 746.05 | AH14: 828.32 | AI14: 1073.2 | AJ14: 1171.2
A15: Depreciation and amortisation expense | B15: INR Mn | C15: Company filings | D15: 194.97 | E15: 213.08 | F15: 251.24 | G15: 304.84 | H15: 310.12 | I15: 385.02 | J15: 507 | K15: 530.42 | L15: 519.2 | M15: 546.36 | N15: 580.28 | O15: 596.49 | P15: 600.6 | Q15: 636.2 | R15: 698.2 | S15: 729 | T15: 761.4 | U15: 790.9 | V15: 808.8 | W15: 842.2 | AC15: 308.76 | AD15: 595.09 | AE15: 671.28 | AF15: 964.13 | AG15: 1732.56 | AH15: 2242.33 | AI15: 2664 | AJ15: 3203.3
A16: Other expenses | B16: INR Mn | C16: Company filings | D16: 2321.16 | E16: 2800.17 | F16: 3464.6 | G16: 2959.42 | H16: 3491.18 | I16: 3748.4 | J16: 4285.94 | K16: 3778.07 | L16: 4065.83 | M16: 4326.75 | N16: 5140.44 | O16: 4748.86 | P16: 5040 | Q16: 5558.7 | R16: 6757.6 | S16: 6015.5 | T16: 6388.1 | U16: 7118.2 | V16: 8648.2 | W16: 7765.3 | AC16: 3133.11 | AD16: 4766.6 | AE16: 5079.98 | AF16: 11547.23 | AG16: 15303.59 | AH16: 18281.89 | AI16: 23371.8 | AJ16: 29919.8
A17: Total Expenses | B17: INR Mn | D17: =SUM(D10:D16) | E17: =SUM(E10:E16) | F17: =SUM(F10:F16) | G17: =SUM(G10:G16) | H17: =SUM(H10:H16) | I17: =SUM(I10:I16) | J17: =SUM(J10:J16) | K17: =SUM(K10:K16) | ... W17: =SUM(W10:W16) | AC17: =SUM(AC10:AC16) | AD17: =SUM(AD10:AD16) | AE17: =SUM(AE10:AE16) | AF17: =SUM(AF10:AF16) | AG17: =SUM(AG10:AG16) | AH17: =SUM(AH10:AH16) | AI17: =SUM(AI10:AI16) | AJ17: =SUM(AJ10:AJ16)
A19: Profit Before Exceptional Items and Tax | B19: INR Mn | D19: =D7-D17 | E19: =E7-E17 | F19: =F7-F17 | G19: =G7-G17 | H19: =H7-H17 | I19: =I7-I17 | J19: =J7-J17 | K19: =K7-K17 | ... W19: =W7-W17 | AC19: =AC7-AC17 | AD19: =AD7-AD17 | AE19: =AE7-AE17 | AF19: =AF7-AF17 | AG19: =AG7-AG17 | AH19: =AH7-AH17 | AI19: =AI7-AI17 | AJ19: =AJ7-AJ17
A20: Exceptional items, net | B20: INR Mn | C20: Company filings | D20: 0 | E20: 0 | F20: 0 | G20: 0 | H20: 0 | I20: 0 | J20: 0 | K20: 0 | L20: 0 | M20: 0 | N20: 0 | O20: 0 | P20: 0 | Q20: 0 | R20: 0 | S20: 0 | T20: 0 | U20: 10.4 | V20: 163.6 | W20: 0 | AC20: 0 | AD20: 0 | AE20: 0 | AF20: 0 | AG20: 0 | AH20: 0 | AI20: 0 | AJ20: 174
A21: Profit Before Tax | B21: INR Mn | D21: =D19-D20 | E21: =E19-E20 | F21: =F19-F20 | G21: =G19-G20 | H21: =H19-H20 | I21: =I19-I20 | J21: =J19-J20 | K21: =K19-K20 | ... W21: =W19-W20 | AC21: =AC19-AC20 | AD21: =AD19-AD20 | AE21: =AE19-AE20 | AF21: =AF19-AF20 | AG21: =AG19-AG20 | AH21: =AH19-AH20 | AI21: =AI19-AI20 | AJ21: =AJ19-AJ20
A23: Tax expense
A24: Current tax | B24: INR Mn | C24: Company filings | D24: 133.64 | E24: 3.66 | F24: 144.35 | G24: 141.28 | H24: 113.25 | I24: 215.91 | J24: 270.99 | K24: 260.96 | L24: 236.23 | M24: 215.86 | N24: 308.98 | O24: 306.28 | P24: 420.3 | Q24: 211.2 | R24: 319.9 | S24: -536.4 | T24: 177.3 | U24: 209.2 | V24: 279.2 | W24: 709.2 | AC24: 0 | AD24: 45.37 | AE24: 400.78 | AF24: 422.93 | AG24: 861.11 | AH24: 1067.35 | AI24: 415 | AJ24: 1374.9
A25: Current tax pertaining to earlier years | B25: INR Mn | C25: Company filings | D25: 0 | E25: 0 | F25: 0 | G25: 23.46 | H25: 0 | I25: 0 | J25: 0 | K25: 0 | L25: 0 | M25: 0 | N25: 0 | O25: 0 | P25: 0 | Q25: 0 | R25: 0 | S25: 0 | T25: 0 | U25: 0 | V25: 0 | W25: 0 | AC25: 0 | AD25: 0 | AE25: 0 | AF25: 23.46 | AG25: 0 | AH25: 0 | AI25: 0 | AJ25: 0
A26: Deferred tax expense/(credit) | B26: INR Mn | C26: Company filings | D26: -137.37 | E26: -1.73 | F26: -64.74 | G26: -124.27 | H26: -86.72 | I26: -184.91 | J26: -236.32 | K26: -217.42 | L26: -203.6 | M26: -176.18 | N26: -226.43 | O26: -208.03 | P26: -341.9 | Q26: -133 | R26: -144 | S26: 741.4 | T26: 15.1 | U26: 14.8 | V26: 139.6 | W26: -281.5 | AC26: -71.81 | AD26: -6.27 | AE26: -266.85 | AF26: -328.11 | AG26: -725.37 | AH26: -814.24 | AI26: 122.5 | AJ26: -112
A27: Deferred tax credit for unrecognised business loss (earlier years) | B27: INR Mn | C27: Company filings | D27: 0 | E27: 0 | F27: 0 | G27: -58.1 | H27: 0 | I27: 0 | J27: 0 | K27: 0 | L27: 0 | M27: 0 | N27: 0 | O27: 0 | P27: 0 | Q27: 0 | R27: 0 | S27: 0 | T27: 0 | U27: 0 | V27: 0 | W27: 0 | AC27: 0 | AD27: 0 | AE27: 0 | AF27: -58.1 | AG27: 0 | AH27: 0 | AI27: 0 | AJ27: 0
A28: Total Tax Expense/(Income) | B28: INR Mn | D28: =SUM(D24:D27) | E28: =SUM(E24:E27) | F28: =SUM(F24:F27) | G28: =SUM(G24:G27) | H28: =SUM(H24:H27) | I28: =SUM(I24:I27) | J28: =SUM(J24:J27) | K28: =SUM(K24:K27) | ... W28: =SUM(W24:W27) | AC28: =SUM(AC24:AC27) | AD28: =SUM(AD24:AD27) | AE28: =SUM(AE24:AE27) | AF28: =SUM(AF24:AF27) | AG28: =SUM(AG24:AG27) | AH28: =SUM(AH24:AH27) | AI28: =SUM(AI24:AI27) | AJ28: =SUM(AJ24:AJ27)
A30: Net Profit After Tax | B30: INR Mn | D30: =D21-D28 | E30: =E21-E28 | F30: =F21-F28 | G30: =G21-G28 | H30: =H21-H28 | I30: =I21-I28 | J30: =J21-J28 | K30: =K21-K28 | ... W30: =W21-W28 | AC30: =AC21-AC28 | AD30: =AD21-AD28 | AE30: =AE21-AE28 | AF30: =AF21-AF28 | AG30: =AG21-AG28 | AH30: =AH21-AH28 | AI30: =AI21-AI28 | AJ30: =AJ21-AJ28
A31: Share in profit/(loss) of associate | B31: INR Mn | C31: Company filings | D31: 0 | E31: 0 | F31: 0 | G31: 0 | H31: -6.77 | I31: -4.64 | J31: -7.19 | K31: -20 | L31: -10.31 | M31: -14.89 | N31: -7.8 | O31: -6.66 | P31: -6 | Q31: -4.7 | R31: -5.6 | S31: 0 | T31: 0 | U31: 0 | V31: 0 | W31: 0 | AC31: 0 | AD31: 0 | AE31: 0 | AF31: 0 | AG31: -38.6 | AH31: -39.67 | AI31: -16.3 | AJ31: 0
A32: Net Profit/(Loss) for the Period | B32: INR Mn | D32: =D30+D31 | E32: =E30+E31 | F32: =F30+F31 | G32: =G30+G31 | H32: =H30+H31 | I32: =I30+I31 | J32: =J30+J31 | K32: =K30+K31 | ... W32: =W30+W31 | AC32: =AC30+AC31 | AD32: =AD30+AD31 | AE32: =AE30+AE31 | AF32: =AF30+AF31 | AG32: =AG30+AG31 | AH32: =AH30+AH31 | AI32: =AI30+AI31 | AJ32: =AJ30+AJ31
A34: Attributable to:
A35: Equity shareholders of parent | B35: INR Mn | C35: Company filings | D35: 34.15 | E35: 11.7 | F35: 279.3 | G35: 85.6 | H35: 45.5 | I35: 41.08 | J35: 81.93 | K35: 24.11 | L35: 33.03 | M35: 58.46 | N35: 161.86 | O35: 69.31 | P35: 96.4 | Q35: 100.4 | R35: 261.2 | S35: 202.8 | T35: 233.2 | U35: 344.3 | V35: 633.1 | W35: 783.8 | AC35: -245.18 | AD35: -166.09 | AE35: 618.48 | AF35: 410.75 | AG35: 192.62 | AH35: 322.65 | AI35: 660.8 | AJ35: 1994.4
A36: Non-controlling interests | B36: INR Mn | C36: Company filings | D36: 1.07 | E36: 0.02 | F36: 10.85 | G36: -9.81 | H36: 4.6 | I36: 10.83 | J36: 2.92 | K36: -1.36 | L36: 21.22 | M36: 19.54 | N36: 12.68 | O36: 21.4 | P36: 40 | Q36: 29.3 | R36: 2.9 | S36: -12.3 | T36: 11.5 | U36: -14.5 | V36: 44.3 | W36: 3.7 | AC36: -0.21 | AD36: 2.69 | AE36: 0.97 | AF36: 2.13 | AG36: 16.99 | AH36: 74.84 | AI36: 59.9 | AJ36: 45
A38: Total Other Comprehensive Income/(Loss), net of tax | B38: INR Mn | C38: Company filings | P38: 0 | Q38: -20.2 | R38: -1.3 | S38: -21.6 | T38: 1.2 | U38: 22.5 | V38: 4.8 | W38: 23.5 | AC38: 2.51 | AD38: 1.09 | AE38: -21.8 | AF38: 5.56 | AG38: 1.57 | AH38: 4.43 | AI38: -43.1 | AJ38: 52 | AL38: =SUM(D38:G38)-AF38 | AM38: =SUM(H38:K38)-AG38 | AN38: =SUM(L38:O38)-AH38
A39: Total Comprehensive Income/(Loss) | B39: INR Mn | D39: =D32+D38 | E39: =E32+E38 | F39: =F32+F38 | G39: =G32+G38 | H39: =H32+H38 | I39: =I32+I38 | J39: =J32+J38 | K39: =K32+K38 | ... W39: =W32+W38 | AC39: =AC32+AC38 | AD39: =AD32+AD38 | AE39: =AE32+AE38 | AF39: =AF32+AF38 | AG39: =AG32+AG38 | AH39: =AH32+AH38 | AI39: =AI32+AI38 | AJ39: =AJ32+AJ38 | AL39: =SUM(D39:G39)-AF39 | AM39: =SUM(H39:K39)-AG39 | AN39: =SUM(L39:O39)-AH39
A41: Basic EPS | B41: INR | C41: Company filings | D41: 0.08 | E41: 0.03 | F41: 0.6 | G41: 0.18 | H41: 0 | I41: 0.01 | J41: 0.03 | K41: 0.01 | L41: 0.02 | M41: 0.02 | N41: 0.06 | O41: 0.02 | P41: 0.03 | Q41: 0.04 | R41: 0.09 | S41: 0.07 | T41: 0.08 | U41: 0.12 | V41: 0.22 | W41: 0.27 | AC41: -17.7 | AD41: -11.63 | AE41: 41.66 | AF41: 0.88 | AG41: 0.07 | AH41: 0.11 | AI41: 0.23 | AJ41: 0.7
A42: Diluted EPS | B42: INR | C42: Company filings | D42: 0.07 | E42: 0.03 | F42: 0.6 | G42: 0.18 | H42: 0 | I42: 0.01 | J42: 0.03 | K42: 0.01 | L42: 0.02 | M42: 0.02 | N42: 0.06 | O42: 0.02 | P42: 0.03 | Q42: 0.04 | R42: 0.09 | S42: 0.07 | T42: 0.08 | U42: 0.12 | V42: 0.22 | W42: 0.27 | AC42: -17.7 | AD42: -11.63 | AE42: 40.07 | AF42: 0.87 | AG42: 0.07 | AH42: 0.11 | AI42: 0.23 | AJ42: 0.7
A43: Note: FY19-FY21 EPS computed on face value of Rs 10/share (Restated Ind AS statements, RHP); face value changed to Re 1/share from FY22 following share sub-division. Not directly comparable across the break.
A46: BALANCE SHEET (CONSOLIDATED)
A47: ASSETS
A48: Non-current assets
A49: Property, plant and equipment | B49: INR Mn | C49: Company filings | G49: 1244.42 | I49: 1713.47 | K49: 2313.46 | M49: 2315.23 | O49: 2357.72 | Q49: 2351.5 | S49: 2717.2 | U49: 2712.6 | W49: 2999.7 | AC49: 429.05 | AD49: 701.49 | AE49: 686.52 | AF49: 1244.42 | AG49: 2313.46 | AH49: 2357.72 | AI49: 2717.2 | AJ49: 2999.7
...

Sheet Raw Data - Ops KPIs
A3: All figures in INR Mn unless stated otherwise.
A5: Metric | B5: Unit | C5: Source - Deck section | D5: Q1FY22 | E5: Q2FY22 | F5: Q3FY22 | G5: Q4FY22 | H5: Q1FY23 | I5: Q2FY23 | J5: Q3FY23 | K5: Q4FY23 | L5: Q1FY24 | M5: Q2FY24 | N5: Q3FY24 | O5: Q4FY24 | P5: Q1FY25 | Q5: Q2FY25 | R5: Q3FY25 | S5: Q4FY25 | T5: Q1FY26 | U5: Q2FY26 | V5: Q3FY26 | W5: Q4FY26 | X5: Q1FY27 | Y5: Q2FY27 | Z5: Q3FY27 | AA5: Q4FY27 | AF5: FY22 | AG5: FY23 | AH5: FY24 | AI5: FY25 | AJ5: FY26
A6: Consolidated Operating KPIs
A7: Number of visits | B7: mn | C7: One Nykaa Highlights | D7: 312.4 | E7: 335 | F7: 347 | G7: 328 | H7: 354 | I7: 372 | J7: 403 | K7: 369 | L7: 395 | M7: 430 | N7: 468 | O7: 447 | AF7: =IF(COUNT(D7:G7)=0,"",SUM(D7:G7)) | AG7: =IF(COUNT(H7:K7)=0,"",SUM(H7:K7)) | AH7: =IF(COUNT(L7:O7)=0,"",SUM(L7:O7)) | AI7: =IF(COUNT(P7:S7)=0,"",SUM(P7:S7)) | AJ7: =IF(COUNT(T7:W7)=0,"",SUM(T7:W7))
A8: Annual transacting customers | B8: mn | C8: One Nykaa Highlights | D8: 7.7 | E8: 8.6 | F8: 9.4 | G8: 10.2 | H8: 11 | I8: 11.7 | J8: 12.5 | K8: 13 | L8: 13.5 | M8: 14 | N8: 14.6 | O8: 15.4 | AF8: =IF(G8="","",G8) | AG8: =IF(K8="","",K8) | AH8: =IF(O8="","",O8) | AI8: =IF(S8="","",S8) | AJ8: =IF(W8="","",W8)
A9: YoY growth | B9: % | H9: =IFERROR(H8/D8-1,"") | I9: =IFERROR(I8/E8-1,"") | J9: =IFERROR(J8/F8-1,"") | K9: =IFERROR(K8/G8-1,"") | L9: =IFERROR(L8/H8-1,"") | M9: =IFERROR(M8/I8-1,"") | N9: =IFERROR(N8/J8-1,"") | O9: =IFERROR(O8/K8-1,"") | ... AA9: =IFERROR(AA8/W8-1,"") | AF9: =IFERROR(AF8/AE8-1,"") | AG9: =IFERROR(AG8/AF8-1,"") | AH9: =IFERROR(AH8/AG8-1,"") | AI9: =IFERROR(AI8/AH8-1,"") | AJ9: =IFERROR(AJ8/AI8-1,"")
A10: Number of orders | B10: mn | C10: One Nykaa Highlights | D10: 7 | E10: 7.4 | F10: 9 | G10: 8.7 | H10: 9.9 | I10: 10.1 | J10: 11.6 | K10: 10.6 | L10: 11.4 | M10: 12.2 | N10: 13.7 | O10: 13.4 | AF10: =IF(COUNT(D10:G10)=0,"",SUM(D10:G10)) | AG10: =IF(COUNT(H10:K10)=0,"",SUM(H10:K10)) | AH10: =IF(COUNT(L10:O10)=0,"",SUM(L10:O10)) | AI10: =IF(COUNT(P10:S10)=0,"",SUM(P10:S10)) | AJ10: =IF(COUNT(T10:W10)=0,"",SUM(T10:W10))
A11: Total GMV | B11: Rs Mn | C11: One Nykaa Highlights | D11: 14696 | E11: 16229 | F11: 20428 | G11: 17979 | H11: 21588 | I11: 23457 | J11: 27965 | K11: 24454 | L11: 26678 | M11: 29435 | N11: 36195 | O11: 32163 | P11: 33209 | Q11: 36525 | R11: 45279 | S11: 41020 | T11: 41820 | U11: 47440 | V11: 57950 | W11: 52410 | AF11: =IF(COUNT(D11:G11)=0,"",SUM(D11:G11)) | AG11: =IF(COUNT(H11:K11)=0,"",SUM(H11:K11)) | AH11: =IF(COUNT(L11:O11)=0,"",SUM(L11:O11)) | AI11: =IF(COUNT(P11:S11)=0,"",SUM(P11:S11)) | AJ11: =IF(COUNT(T11:W11)=0,"",SUM(T11:W11))
A12: YoY growth | B12: % | H12: =IFERROR(H11/D11-1,"") | I12: =IFERROR(I11/E11-1,"") | J12: =IFERROR(J11/F11-1,"") | K12: =IFERROR(K11/G11-1,"") | L12: =IFERROR(L11/H11-1,"") | M12: =IFERROR(M11/I11-1,"") | N12: =IFERROR(N11/J11-1,"") | O12: =IFERROR(O11/K11-1,"") | ... AA12: =IFERROR(AA11/W11-1,"") | AF12: =IFERROR(AF11/AE11-1,"") | AG12: =IFERROR(AG11/AF11-1,"") | AH12: =IFERROR(AH11/AG11-1,"") | AI12: =IFERROR(AI11/AH11-1,"") | AJ12: =IFERROR(AJ11/AI11-1,"")
A13: QoQ growth | B13: % | E13: =IFERROR(E11/D11-1,"") | F13: =IFERROR(F11/E11-1,"") | G13: =IFERROR(G11/F11-1,"") | H13: =IFERROR(H11/G11-1,"") | I13: =IFERROR(I11/H11-1,"") | J13: =IFERROR(J11/I11-1,"") | K13: =IFERROR(K11/J11-1,"") | L13: =IFERROR(L11/K11-1,"") | ... AA13: =IFERROR(AA11/Z11-1,"")
A14: Total NSV | B14: Rs Mn | C14: One Nykaa Highlights | D14: 8050 | E14: 8688 | F14: 10729 | G14: 9650 | H14: 11272 | I14: 12049 | J14: 14401 | K14: 12904 | L14: 14205 | M14: 14982 | N14: 17866 | O14: 16489 | P14: 17183 | Q14: 18432 | R14: 22190 | S14: 20430 | T14: 21370 | U14: 23400 | V14: 28440 | W14: 26780 | AF14: =IF(COUNT(D14:G14)=0,"",SUM(D14:G14)) | AG14: =IF(COUNT(H14:K14)=0,"",SUM(H14:K14)) | AH14: =IF(COUNT(L14:O14)=0,"",SUM(L14:O14)) | AI14: =IF(COUNT(P14:S14)=0,"",SUM(P14:S14)) | AJ14: =IF(COUNT(T14:W14)=0,"",SUM(T14:W14))
A15: NSV / GMV | B15: % | D15: =IFERROR(D14/D11,"") | E15: =IFERROR(E14/E11,"") | F15: =IFERROR(F14/F11,"") | G15: =IFERROR(G14/G11,"") | H15: =IFERROR(H14/H11,"") | I15: =IFERROR(I14/I11,"") | J15: =IFERROR(J14/J11,"") | K15: =IFERROR(K14/K11,"") | ... AA15: =IFERROR(AA14/AA11,"") | AF15: =IFERROR(AF14/AF11,"") | AG15: =IFERROR(AG14/AG11,"") | AH15: =IFERROR(AH14/AH11,"") | AI15: =IFERROR(AI14/AI11,"") | AJ15: =IFERROR(AJ14/AJ11,"")
A16: Total Revenue | B16: Rs Mn | C16: One Nykaa Highlights / Financial Performance | D16: 8169.91 | E16: 8852.64 | F16: 10983.6 | G16: 9733.2 | H16: 11484.21 | I16: 12308.29 | J16: 14628.26 | K16: 13017.24 | L16: 14218.24 | M16: 15070.24 | N16: 17887.98 | O16: 16679.8 | P16: 17461.1 | Q16: 18747.4 | R16: 22672.1 | S16: 20617.6 | T16: 21549.4 | U16: 23459.8 | V16: 28732.6 | W16: 26480 | AF16: =IF(COUNT(D16:G16)=0,"",SUM(D16:G16)) | AG16: =IF(COUNT(H16:K16)=0,"",SUM(H16:K16)) | AH16: =IF(COUNT(L16:O16)=0,"",SUM(L16:O16)) | AI16: =IF(COUNT(P16:S16)=0,"",SUM(P16:S16)) | AJ16: =IF(COUNT(T16:W16)=0,"",SUM(T16:W16))
A17: YoY growth | B17: % | H17: =IFERROR(H16/D16-1,"") | I17: =IFERROR(I16/E16-1,"") | J17: =IFERROR(J16/F16-1,"") | K17: =IFERROR(K16/G16-1,"") | L17: =IFERROR(L16/H16-1,"") | M17: =IFERROR(M16/I16-1,"") | N17: =IFERROR(N16/J16-1,"") | O17: =IFERROR(O16/K16-1,"") | ... AA17: =IFERROR(AA16/W16-1,"") | AF17: =IFERROR(AF16/AE16-1,"") | AG17: =IFERROR(AG16/AF16-1,"") | AH17: =IFERROR(AH16/AG16-1,"") | AI17: =IFERROR(AI16/AH16-1,"") | AJ17: =IFERROR(AJ16/AI16-1,"")
A18: Revenue / NSV | B18: % | D18: =IFERROR(D16/D14,"") | E18: =IFERROR(E16/E14,"") | F18: =IFERROR(F16/F14,"") | G18: =IFERROR(G16/G14,"") | H18: =IFERROR(H16/H14,"") | I18: =IFERROR(I16/I14,"") | J18: =IFERROR(J16/J14,"") | K18: =IFERROR(K16/K14,"") | ... AA18: =IFERROR(AA16/AA14,"") | AF18: =IFERROR(AF16/AF14,"") | AG18: =IFERROR(AG16/AG14,"") | AH18: =IFERROR(AH16/AH14,"") | AI18: =IFERROR(AI16/AI14,"") | AJ18: =IFERROR(AJ16/AJ14,"")
A19: Gross profit | B19: Rs Mn | C19: Financial Performance (Total column) | D19: 3316.59 | E19: 3782.42 | F19: 5087.58 | G19: 4252.61 | H19: 5098.79 | I19: 5577.38 | J19: 6346.7 | K19: 5758.32 | L19: 6186.25 | M19: 6496.24 | N19: 7607.48 | O19: 7102.43 | P19: 7559.8 | Q19: 8210.2 | R19: 9911.4 | S19: 9090.2 | T19: 9615.1 | U19: 10535.4 | V19: 12974.8 | W19: 12030 | AF19: =IF(COUNT(D19:G19)=0,"",SUM(D19:G19)) | AG19: =IF(COUNT(H19:K19)=0,"",SUM(H19:K19)) | AH19: =IF(COUNT(L19:O19)=0,"",SUM(L19:O19)) | AI19: =IF(COUNT(P19:S19)=0,"",SUM(P19:S19)) | AJ19: =IF(COUNT(T19:W19)=0,"",SUM(T19:W19))
A20: Gross margin (% of NSV) | B20: % | D20: =IFERROR(D19/D14,"") | E20: =IFERROR(E19/E14,"") | F20: =IFERROR(F19/F14,"") | G20: =IFERROR(G19/G14,"") | H20: =IFERROR(H19/H14,"") | I20: =IFERROR(I19/I14,"") | J20: =IFERROR(J19/J14,"") | K20: =IFERROR(K19/K14,"") | ... AA20: =IFERROR(AA19/AA14,"") | AF20: =IFERROR(AF19/AF14,"") | AG20: =IFERROR(AG19/AG14,"") | AH20: =IFERROR(AH19/AH14,"") | AI20: =IFERROR(AI19/AI14,"") | AJ20: =IFERROR(AJ19/AJ14,"")
A21: Fulfilment cost | B21: Rs Mn | C21: Financial Performance (Total column) | D21: 934 | E21: 910 | F21: 1162 | G21: 949 | H21: 1294 | I21: 1454 | J21: 1288 | K21: 1286 | L21: 1357 | M21: 1459 | N21: 1718 | O21: 1550 | P21: 1667 | Q21: 1748 | R21: 2090 | S21: 1920 | T21: 2030 | U21: 2270 | V21: 2690 | W21: 2600 | AF21: =IF(COUNT(D21:G21)=0,"",SUM(D21:G21)) | AG21: =IF(COUNT(H21:K21)=0,"",SUM(H21:K21)) | AH21: =IF(COUNT(L21:O21)=0,"",SUM(L21:O21)) | AI21: =IF(COUNT(P21:S21)=0,"",SUM(P21:S21)) | AJ21: =IF(COUNT(T21:W21)=0,"",SUM(T21:W21))
A22: Marketing & S&D expense (combined) | B22: Rs Mn | C22: Financial Performance (Total column) | D22: 1099 | E22: 1521 | F22: 1846 | G22: 1561 | H22: 1524 | I22: 1635 | J22: 1982 | K22: 1670 | L22: 1919 | M22: 2036 | N22: 2558 | O22: 2361 | P22: 2483 | Q22: 2767 | R22: 3620 | S22: 3160 | T22: 3180 | U22: 3560 | V22: 4380 | W22: 3740 | AF22: =IF(COUNT(D22:G22)=0,"",SUM(D22:G22)) | AG22: =IF(COUNT(H22:K22)=0,"",SUM(H22:K22)) | AH22: =IF(COUNT(L22:O22)=0,"",SUM(L22:O22)) | AI22: =IF(COUNT(P22:S22)=0,"",SUM(P22:S22)) | AJ22: =IF(COUNT(T22:W22)=0,"",SUM(T22:W22))
A23: Contribution profit | B23: Rs Mn | D23: =IF(OR(ISBLANK(D19),ISBLANK(D21),ISBLANK(D22)),"",IFERROR(D19-D21-D22,"")) | E23: =IF(OR(ISBLANK(E19),ISBLANK(E21),ISBLANK(E22)),"",IFERROR(E19-E21-E22,"")) | F23: =IF(OR(ISBLANK(F19),ISBLANK(F21),ISBLANK(F22)),"",IFERROR(F19-F21-F22,"")) | G23: =IF(OR(ISBLANK(G19),ISBLANK(G21),ISBLANK(G22)),"",IFERROR(G19-G21-G22,"")) | H23: =IF(OR(ISBLANK(H19),ISBLANK(H21),ISBLANK(H22)),"",IFERROR(H19-H21-H22,"")) | I23: =IF(OR(ISBLANK(I19),ISBLANK(I21),ISBLANK(I22)),"",IFERROR(I19-I21-I22,"")) | J23: =IF(OR(ISBLANK(J19),ISBLANK(J21),ISBLANK(J22)),"",IFERROR(J19-J21-J22,"")) | K23: =IF(OR(ISBLANK(K19),ISBLANK(K21),ISBLANK(K22)),"",IFERROR(K19-K21-K22,"")) | ... AA23: =IF(OR(ISBLANK(AA19),ISBLANK(AA21),ISBLANK(AA22)),"",IFERROR(AA19-AA21-AA22,"")) | AF23: =IF(OR(ISBLANK(AF19),ISBLANK(AF21),ISBLANK(AF22)),"",IFERROR(AF19-AF21-AF22,"")) | AG23: =IF(OR(ISBLANK(AG19),ISBLANK(AG21),ISBLANK(AG22)),"",IFERROR(AG19-AG21-AG22,"")) | AH23: =IF(OR(ISBLANK(AH19),ISBLANK(AH21),ISBLANK(AH22)),"",IFERROR(AH19-AH21-AH22,"")) | AI23: =IF(OR(ISBLANK(AI19),ISBLANK(AI21),ISBLANK(AI22)),"",IFERROR(AI19-AI21-AI22,"")) | AJ23: =IF(OR(ISBLANK(AJ19),ISBLANK(AJ21),ISBLANK(AJ22)),"",IFERROR(AJ19-AJ21-AJ22,""))
A24: Contribution margin (% of NSV) | B24: % | D24: =IFERROR(D23/D14,"") | E24: =IFERROR(E23/E14,"") | F24: =IFERROR(F23/F14,"") | G24: =IFERROR(G23/G14,"") | H24: =IFERROR(H23/H14,"") | I24: =IFERROR(I23/I14,"") | J24: =IFERROR(J23/J14,"") | K24: =IFERROR(K23/K14,"") | ... AA24: =IFERROR(AA23/AA14,"") | AF24: =IFERROR(AF23/AF14,"") | AG24: =IFERROR(AG23/AG14,"") | AH24: =IFERROR(AH23/AH14,"") | AI24: =IFERROR(AI23/AI14,"") | AJ24: =IFERROR(AJ23/AJ14,"")
A25: Other expenses (G&A + employee) | B25: Rs Mn | C25: Financial Performance (Total column) | D25: 1014.15 | E25: 1063.18 | F25: 1735.81 | G25: 1357 | H25: 1820.27 | I25: 1877.01 | J25: 2295.1 | K25: 2095.38 | L25: 2175.59 | M25: 2194.95 | N25: 2343.74 | O25: 2258.61 | P25: 2448.6 | Q25: 2658.6 | R25: 2793.6 | S25: 2676.7 | T25: 2898.3 | U25: 2995.9 | V25: 3387.2 | W25: 3470 | AF25: =IF(COUNT(D25:G25)=0,"",SUM(D25:G25)) | AG25: =IF(COUNT(H25:K25)=0,"",SUM(H25:K25)) | AH25: =IF(COUNT(L25:O25)=0,"",SUM(L25:O25)) | AI25: =IF(COUNT(P25:S25)=0,"",SUM(P25:S25)) | AJ25: =IF(COUNT(T25:W25)=0,"",SUM(T25:W25))
A26: EBITDA | B26: Rs Mn | D26: =IF(OR(ISBLANK(D23),ISBLANK(D25)),"",IFERROR(D23-D25,"")) | E26: =IF(OR(ISBLANK(E23),ISBLANK(E25)),"",IFERROR(E23-E25,"")) | F26: =IF(OR(ISBLANK(F23),ISBLANK(F25)),"",IFERROR(F23-F25,"")) | G26: =IF(OR(ISBLANK(G23),ISBLANK(G25)),"",IFERROR(G23-G25,"")) | H26: =IF(OR(ISBLANK(H23),ISBLANK(H25)),"",IFERROR(H23-H25,"")) | I26: =IF(OR(ISBLANK(I23),ISBLANK(I25)),"",IFERROR(I23-I25,"")) | J26: =IF(OR(ISBLANK(J23),ISBLANK(J25)),"",IFERROR(J23-J25,"")) | K26: =IF(OR(ISBLANK(K23),ISBLANK(K25)),"",IFERROR(K23-K25,"")) | ... AA26: =IF(OR(ISBLANK(AA23),ISBLANK(AA25)),"",IFERROR(AA23-AA25,"")) | AF26: =IF(OR(ISBLANK(AF23),ISBLANK(AF25)),"",IFERROR(AF23-AF25,"")) | AG26: =IF(OR(ISBLANK(AG23),ISBLANK(AG25)),"",IFERROR(AG23-AG25,"")) | AH26: =IF(OR(ISBLANK(AH23),ISBLANK(AH25)),"",IFERROR(AH23-AH25,"")) | AI26: =IF(OR(ISBLANK(AI23),ISBLANK(AI25)),"",IFERROR(AI23-AI25,"")) | AJ26: =IF(OR(ISBLANK(AJ23),ISBLANK(AJ25)),"",IFERROR(AJ23-AJ25,""))
A27: EBITDA margin (% of NSV) | B27: % | D27: =IFERROR(D26/D14,"") | E27: =IFERROR(E26/E14,"") | F27: =IFERROR(F26/F14,"") | G27: =IFERROR(G26/G14,"") | H27: =IFERROR(H26/H14,"") | I27: =IFERROR(I26/I14,"") | J27: =IFERROR(J26/J14,"") | K27: =IFERROR(K26/K14,"") | ... AA27: =IFERROR(AA26/AA14,"") | AF27: =IFERROR(AF26/AF14,"") | AG27: =IFERROR(AG26/AG14,"") | AH27: =IFERROR(AH26/AH14,"") | AI27: =IFERROR(AI26/AI14,"") | AJ27: =IFERROR(AJ26/AJ14,"")
A29: Beauty (incl. SuperStore) - Omnichannel Retail
A30: Definition: BPC (online + offline) + Superstore by Nykaa + Nykaa Man Grooming + House of Nykaa owned brands
A31: Number of visits | B31: mn | C31: Beauty Omnichannel Retail | D31: 205 | E31: 211 | F31: 221 | G31: 204 | H31: 222 | I31: 234 | J31: 250 | K31: 231 | L31: 269 | M31: 287 | N31: 311 | O31: 303 | P31: 330 | Q31: 357 | R31: 401 | S31: 393 | T31: 411 | U31: 450 | V31: 538 | W31: =AJ31-SUM(T31:V31) | AF31: =IF(COUNT(D31:G31)=0,"",SUM(D31:G31)) | AG31: =IF(COUNT(H31:K31)=0,"",SUM(H31:K31)) | AH31: =IF(COUNT(L31:O31)=0,"",SUM(L31:O31)) | AI31: =IF(COUNT(P31:S31)=0,"",SUM(P31:S31)) | AJ31: 1894
A32: Monthly average unique visitors | B32: mn | C32: Beauty Omnichannel Retail | D32: 17.3 | E32: 19.4 | F32: 19.8 | G32: 18.5 | H32: 21.8 | I32: 22.1 | J32: 24.2 | K32: 22.5 | L32: 27.3 | M32: 26.8 | N32: 29.6 | O32: 31.9 | P32: 32.6 | Q32: 34.2 | R32: 38.1 | S32: 38 | T32: 38.8 | U32: 41.6 | V32: 50.7 | AF32: =IFERROR(AVERAGE(D32:G32),"") | AG32: =IFERROR(AVERAGE(H32:K32),"") | AH32: 30.2 | AI32: =IFERROR(AVERAGE(P32:S32),"") | AJ32: 44.7
A33: Conversion - orders/visits | B33: % | D33: =IFERROR(D37/D31,"") | E33: =IFERROR(E37/E31,"") | F33: =IFERROR(F37/F31,"") | G33: =IFERROR(G37/G31,"") | H33: =IFERROR(H37/H31,"") | I33: =IFERROR(I37/I31,"") | J33: =IFERROR(J37/J31,"") | K33: =IFERROR(K37/K31,"") | ... AA33: =IFERROR(AA37/AA31,"") | AF33: =IFERROR(AF37/AF31,"") | AG33: =IFERROR(AG37/AG31,"") | AH33: =IFERROR(AH37/AH31,"") | AI33: =IFERROR(AI37/AI31,"") | AJ33: =IFERROR(AJ37/AJ31,"")
A34: Conversion - transacting customers/visits | B34: % | D34: =IFERROR(D35/D31,"") | E34: =IFERROR(E35/E31,"") | F34: =IFERROR(F35/F31,"") | G34: =IFERROR(G35/G31,"") | H34: =IFERROR(H35/H31,"") | I34: =IFERROR(I35/I31,"") | J34: =IFERROR(J35/J31,"") | K34: =IFERROR(K35/K31,"") | ... AA34: =IFERROR(AA35/AA31,"") | AF34: =IFERROR(AF35/AF31,"") | AG34: =IFERROR(AG35/AG31,"") | AH34: =IFERROR(AH35/AH31,"") | AI34: =IFERROR(AI35/AI31,"") | AJ34: =IFERROR(AJ35/AJ31,"")
A35: Annual transacting customers | B35: mn | C35: Beauty Omnichannel Retail | D35: 6.5 | E35: 7 | F35: 7.5 | G35: 8 | H35: 8.6 | I35: 9.1 | J35: 9.6 | K35: 10 | L35: 10.9 | M35: 10.7 | N35: 11.7 | O35: 12.4 | P35: 13.1 | Q35: 13.7 | R35: 14.8 | S35: 15.8 | T35: 16.5 | U35: 17.5 | V35: 18.7 | W35: 19.7 | AF35: =IF(G35="","",G35) | AG35: =IF(K35="","",K35) | AH35: =IF(O35="","",O35) | AI35: =IF(S35="","",S35) | AJ35: =IF(W35="","",W35)
A36: Average order frequency | B36: x | D36: =IFERROR(D37*4/D35,"") | E36: =IFERROR(E37*4/E35,"") | F36: =IFERROR(F37*4/F35,"") | G36: =IFERROR(G37*4/G35,"") | H36: =IFERROR(H37*4/H35,"") | I36: =IFERROR(I37*4/I35,"") | J36: =IFERROR(J37*4/J35,"") | K36: =IFERROR(K37*4/K35,"") | ... AA36: =IFERROR(AA37*4/AA35,"") | AF36: =IFERROR(AF37*4/AF35,"") | AG36: =IFERROR(AG37*4/AG35,"") | AH36: =IFERROR(AH37*4/AH35,"") | AI36: =IFERROR(AI37*4/AI35,"") | AJ36: =IFERROR(AJ37*4/AJ35,"")
A37: Number of orders | B37: mn | C37: Beauty Omnichannel Retail | D37: 5.8 | E37: 6 | F37: 7.5 | G37: 7.2 | H37: 8.1 | I37: 8.4 | J37: 9.5 | K37: 8.8 | L37: 9.9 | M37: 10.5 | N37: 11.6 | O37: 11.7 | P37: 12.4 | Q37: 12.9 | R37: 15 | S37: 14.2 | T37: 14.5 | U37: 15.7 | V37: 18.1 | W37: =AJ37-SUM(T37:V37) | AF37: =IF(COUNT(D37:G37)=0,"",SUM(D37:G37)) | AG37: =IF(COUNT(H37:K37)=0,"",SUM(H37:K37)) | AH37: =IF(COUNT(L37:O37)=0,"",SUM(L37:O37)) | AI37: =IF(COUNT(P37:S37)=0,"",SUM(P37:S37)) | AJ37: 65.8
A38: Average order value | B38: Rs | D38: =IFERROR(D39/D37,"") | E38: =IFERROR(E39/E37,"") | F38: =IFERROR(F39/F37,"") | G38: =IFERROR(G39/G37,"") | H38: =IFERROR(H39/H37,"") | I38: =IFERROR(I39/I37,"") | J38: =IFERROR(J39/J37,"") | K38: =IFERROR(K39/K37,"") | ... AA38: =IFERROR(AA39/AA37,"") | AF38: =IFERROR(AF39/AF37,"") | AG38: =IFERROR(AG39/AG37,"") | AH38: =IFERROR(AH39/AH37,"") | AI38: =IFERROR(AI39/AI37,"") | AJ38: =IFERROR(AJ39/AJ37,"")
A39: GMV | B39: Rs Mn | C39: Beauty Omnichannel Retail | L39: 19908 | M39: 21559 | N39: 25696 | O39: 23390 | P39: 25429 | Q39: 27833 | R39: 33899 | S39: 30580 | T39: 32080 | U39: 35510 | V39: 43020 | W39: 38920 | AF39: =IF(COUNT(D39:G39)=0,"",SUM(D39:G39)) | AG39: =IF(COUNT(H39:K39)=0,"",SUM(H39:K39)) | AH39: =IF(COUNT(L39:O39)=0,"",SUM(L39:O39)) | AI39: =IF(COUNT(P39:S39)=0,"",SUM(P39:S39)) | AJ39: =IF(COUNT(T39:W39)=0,"",SUM(T39:W39))
A40: YoY growth | B40: % | H40: =IFERROR(H39/D39-1,"") | I40: =IFERROR(I39/E39-1,"") | J40: =IFERROR(J39/F39-1,"") | K40: =IFERROR(K39/G39-1,"") | L40: =IFERROR(L39/H39-1,"") | M40: =IFERROR(M39/I39-1,"") | N40: =IFERROR(N39/J39-1,"") | O40: =IFERROR(O39/K39-1,"") | ... AA40: =IFERROR(AA39/W39-1,"") | AF40: =IFERROR(AF39/AE39-1,"") | AG40: =IFERROR(AG39/AF39-1,"") | AH40: =IFERROR(AH39/AG39-1,"") | AI40: =IFERROR(AI39/AH39-1,"") | AJ40: =IFERROR(AJ39/AI39-1,"")
A41: QoQ growth | B41: % | E41: =IFERROR(E39/D39-1,"") | F41: =IFERROR(F39/E39-1,"") | G41: =IFERROR(G39/F39-1,"") | H41: =IFERROR(H39/G39-1,"") | I41: =IFERROR(I39/H39-1,"") | J41: =IFERROR(J39/I39-1,"") | K41: =IFERROR(K39/J39-1,"") | L41: =IFERROR(L39/K39-1,"") | ... AA41: =IFERROR(AA39/Z39-1,"")
A42: NSV | B42: Rs Mn | C42: Beauty Omnichannel Retail | L42: 12121 | M42: 12566 | N42: 14954 | O42: 13979 | P42: 14695 | Q42: 15661 | R42: 18817 | S42: 17570 | T42: 18340 | U42: 19810 | V42: 24210 | W42: 22690 | AF42: =IF(COUNT(D42:G42)=0,"",SUM(D42:G42)) | AG42: =IF(COUNT(H42:K42)=0,"",SUM(H42:K42)) | AH42: =IF(COUNT(L42:O42)=0,"",SUM(L42:O42)) | AI42: =IF(COUNT(P42:S42)=0,"",SUM(P42:S42)) | AJ42: =IF(COUNT(T42:W42)=0,"",SUM(T42:W42))
A43: NSV / GMV | B43: % | D43: =IFERROR(D42/D39,"") | E43: =IFERROR(E42/E39,"") | F43: =IFERROR(F42/F39,"") | G43: =IFERROR(G42/G39,"") | H43: =IFERROR(H42/H39,"") | I43: =IFERROR(I42/I39,"") | J43: =IFERROR(J42/J39,"") | K43: =IFERROR(K42/K39,"") | ... AA43: =IFERROR(AA42/AA39,"") | AF43: =IFERROR(AF42/AF39,"") | AG43: =IFERROR(AG42/AG39,"") | AH43: =IFERROR(AH42/AH39,"") | AI43: =IFERROR(AI42/AI39,"") | AJ43: =IFERROR(AJ42/AJ39,"")
A44: Revenue | B44: Rs Mn | C44: Beauty Omnichannel Retail / Financial Performance | L44: 12984 | N44: 16227 | O44: 15190 | P44: 15935 | Q44: 17029 | R44: 20601 | S44: 18950 | T44: 19750 | U44: 21320 | V44: 26220 | W44: 24100 | AF44: =IF(COUNT(D44:G44)=0,"",SUM(D44:G44)) | AG44: =IF(COUNT(H44:K44)=0,"",SUM(H44:K44)) | AH44: =IF(COUNT(L44:O44)=0,"",SUM(L44:O44)) | AI44: =IF(COUNT(P44:S44)=0,"",SUM(P44:S44)) | AJ44: =IF(COUNT(T44:W44)=0,"",SUM(T44:W44))
...

Sheet Financial Statements
A1: INR Mn | B1: Unit | C1: Source | D1: 1Q22 | E1: 2Q22 | F1: 3Q22 | G1: 4Q22 | H1: 1Q23 | I1: 2Q23 | J1: 3Q23 | K1: 4Q23 | L1: 1Q24 | M1: 2Q24 | N1: 3Q24 | O1: 4Q24 | P1: 1Q25 | Q1: 2Q25 | R1: 3Q25 | S1: 4Q25 | T1: 1Q26 | U1: 2Q26 | V1: 3Q26 | W1: 4Q26 | X1: 1Q27 | Y1: 2Q27 | Z1: 3Q27 | AA1: 4Q27 | AC1: FY19 | AD1: FY20 | AE1: FY21 | AF1: FY22 | AG1: FY23 | AH1: FY24 | AI1: FY25 | AJ1: FY26 | AK1: FY27E | AL1: FY28E | AM1: FY29E | AN1: FY30E
A2: Fiscal Year End | D2: =DATE(2021,6,30) | E2: =EOMONTH(D2,-3) | F2: =EOMONTH(E2,-3) | G2: =EOMONTH(F2,-3) | H2: =EOMONTH(G2,-3) | I2: =EOMONTH(H2,-3) | J2: =EOMONTH(I2,-3) | K2: =EOMONTH(J2,-3) | L2: =EOMONTH(K2,-3) | ... AA2: =EOMONTH(Z2,-3) | AC2: =DATE(2019,3,31) | AD2: =DATE(2020,3,31) | AE2: =DATE(2021,3,31) | AF2: =DATE(2022,3,31) | AG2: =DATE(2023,3,31) | AH2: =DATE(2024,3,31) | AI2: =DATE(2025,3,31) | AJ2: =DATE(2026,3,31) | AK2: =DATE(2027,3,31) | AL2: =DATE(2028,3,31) | AM2: =DATE(2029,3,31) | AN2: =DATE(2030,3,31)
A3: All figures in INR Mn unless stated otherwise. This sheet is a reported-format presentation, linked to the Projections sheet (KPI/PnL/BS builds) and to Raw Data - financials (for historical line-item granularity Projections doesn't carry). Where the Projections sheet only models a combined or summarized figure, the projected columns (FY27E-30E) show that combined value on ONE representative line within the group and leave the other reported sub-lines blank -- add your own split assumptions there if/when you want more granularity. Historical quarters/years are actuals, linked either from Projections (for figures already tied there) or directly from Raw Data - financials. Balance Sheet follows Nykaa's own disclosure cadence (Q2/Q4 only); Cash Flow is disclosed annually only, so both sections are annual-only in the projected columns and Q2/Q4-only historically.
A4: PROFIT & LOSS (CONSOLIDATED, REPORTED FORMAT)
A5: Revenue, Other income, COGS (combined), Employee benefits, Finance costs, D&A, Other expenses (plug), Tax (combined) and PAT/EPS are the SAME figures as the Projections sheet's Consolidated P&L block -- linked, not re-derived. The individual reported sub-lines below each combined line (e.g. 'Purchase of traded goods', 'Current tax pertaining to earlier years') are actuals for historical periods but are not separately modeled for FY27E-30E, so they show 0 there -- the full projected value sits on the first sub-line of each group (Cost of material consumed; Current tax).
A6: Revenue from operations | B6: Rs Mn | D6: =IF('Raw Data - financials'!D5="","",'Raw Data - financials'!D5) | E6: =IF('Raw Data - financials'!E5="","",'Raw Data - financials'!E5) | F6: =IF('Raw Data - financials'!F5="","",'Raw Data - financials'!F5) | G6: =IF('Raw Data - financials'!G5="","",'Raw Data - financials'!G5) | H6: =IF('Raw Data - financials'!H5="","",'Raw Data - financials'!H5) | I6: =IF('Raw Data - financials'!I5="","",'Raw Data - financials'!I5) | J6: =IF('Raw Data - financials'!J5="","",'Raw Data - financials'!J5) | K6: =IF('Raw Data - financials'!K5="","",'Raw Data - financials'!K5) | ... W6: =IF('Raw Data - financials'!W5="","",'Raw Data - financials'!W5) | AC6: =IF('Raw Data - financials'!AC5="","",'Raw Data - financials'!AC5) | AD6: =IF('Raw Data - financials'!AD5="","",'Raw Data - financials'!AD5) | AE6: =IF('Raw Data - financials'!AE5="","",'Raw Data - financials'!AE5) | AF6: =IF('Raw Data - financials'!AF5="","",'Raw Data - financials'!AF5) | AG6: =IF('Raw Data - financials'!AG5="","",'Raw Data - financials'!AG5) | AH6: =IF('Raw Data - financials'!AH5="","",'Raw Data - financials'!AH5) | AI6: =IF('Raw Data - financials'!AI5="","",'Raw Data - financials'!AI5) | AJ6: =IF('Raw Data - financials'!AJ5="","",'Raw Data - financials'!AJ5) | AK6: =IF('Projections'!AK118="","",'Projections'!AK118) | AL6: =IF('Projections'!AL118="","",'Projections'!AL118) | AM6: =IF('Projections'!AM118="","",'Projections'!AM118) | AN6: =IF('Projections'!AN118="","",'Projections'!AN118)
A7: Other income | B7: Rs Mn | D7: =IF('Projections'!D119="","",'Projections'!D119) | E7: =IF('Projections'!E119="","",'Projections'!E119) | F7: =IF('Projections'!F119="","",'Projections'!F119) | G7: =IF('Projections'!G119="","",'Projections'!G119) | H7: =IF('Projections'!H119="","",'Projections'!H119) | I7: =IF('Projections'!I119="","",'Projections'!I119) | J7: =IF('Projections'!J119="","",'Projections'!J119) | K7: =IF('Projections'!K119="","",'Projections'!K119) | ... W7: =IF('Projections'!W119="","",'Projections'!W119) | AC7: =IF('Projections'!AC119="","",'Projections'!AC119) | AD7: =IF('Projections'!AD119="","",'Projections'!AD119) | AE7: =IF('Projections'!AE119="","",'Projections'!AE119) | AF7: =IF('Projections'!AF119="","",'Projections'!AF119) | AG7: =IF('Projections'!AG119="","",'Projections'!AG119) | AH7: =IF('Projections'!AH119="","",'Projections'!AH119) | AI7: =IF('Projections'!AI119="","",'Projections'!AI119) | AJ7: =IF('Projections'!AJ119="","",'Projections'!AJ119) | ... AN7: =IF('Projections'!AN119="","",'Projections'!AN119)
A8: Total Income | B8: Rs Mn | D8: =IFERROR(D6+D7,"") | E8: =IFERROR(E6+E7,"") | F8: =IFERROR(F6+F7,"") | G8: =IFERROR(G6+G7,"") | H8: =IFERROR(H6+H7,"") | I8: =IFERROR(I6+I7,"") | J8: =IFERROR(J6+J7,"") | K8: =IFERROR(K6+K7,"") | ... W8: =IFERROR(W6+W7,"") | AC8: =IFERROR(AC6+AC7,"") | AD8: =IFERROR(AD6+AD7,"") | AE8: =IFERROR(AE6+AE7,"") | AF8: =IFERROR(AF6+AF7,"") | AG8: =IFERROR(AG6+AG7,"") | AH8: =IFERROR(AH6+AH7,"") | AI8: =IFERROR(AI6+AI7,"") | AJ8: =IFERROR(AJ6+AJ7,"") | ... AN8: =IFERROR(AN6+AN7,"")
A10: Expenses
A11: Cost of material consumed | B11: Rs Mn | D11: =IF('Raw Data - financials'!D10="","",'Raw Data - financials'!D10) | E11: =IF('Raw Data - financials'!E10="","",'Raw Data - financials'!E10) | F11: =IF('Raw Data - financials'!F10="","",'Raw Data - financials'!F10) | G11: =IF('Raw Data - financials'!G10="","",'Raw Data - financials'!G10) | H11: =IF('Raw Data - financials'!H10="","",'Raw Data - financials'!H10) | I11: =IF('Raw Data - financials'!I10="","",'Raw Data - financials'!I10) | J11: =IF('Raw Data - financials'!J10="","",'Raw Data - financials'!J10) | K11: =IF('Raw Data - financials'!K10="","",'Raw Data - financials'!K10) | ... W11: =IF('Raw Data - financials'!W10="","",'Raw Data - financials'!W10) | AC11: =IF('Raw Data - financials'!AC10="","",'Raw Data - financials'!AC10) | AD11: =IF('Raw Data - financials'!AD10="","",'Raw Data - financials'!AD10) | AE11: =IF('Raw Data - financials'!AE10="","",'Raw Data - financials'!AE10) | AF11: =IF('Raw Data - financials'!AF10="","",'Raw Data - financials'!AF10) | AG11: =IF('Raw Data - financials'!AG10="","",'Raw Data - financials'!AG10) | AH11: =IF('Raw Data - financials'!AH10="","",'Raw Data - financials'!AH10) | AI11: =IF('Raw Data - financials'!AI10="","",'Raw Data - financials'!AI10) | AJ11: =IF('Raw Data - financials'!AJ10="","",'Raw Data - financials'!AJ10) | AK11: =IF('Projections'!AK123="","",'Projections'!AK123) | AL11: =IF('Projections'!AL123="","",'Projections'!AL123) | AM11: =IF('Projections'!AM123="","",'Projections'!AM123) | AN11: =IF('Projections'!AN123="","",'Projections'!AN123)
