Workbook

Sheet Projections
A1: INR Mn | B1: Unit | C1: Source / Driver | D1: 1Q22 | E1: 2Q22 | F1: 3Q22 | G1: 4Q22 | H1: 1Q23 | I1: 2Q23 | J1: 3Q23 | K1: 4Q23 | L1: 1Q24 | M1: 2Q24 | N1: 3Q24 | O1: 4Q24 | P1: 1Q25 | Q1: 2Q25 | R1: 3Q25 | S1: 4Q25 | T1: 1Q26 | U1: 2Q26 | V1: 3Q26 | W1: 4Q26 | X1: 1Q27 | Y1: 2Q27 | Z1: 3Q27 | AA1: 4Q27 | AC1: FY19 | AD1: FY20 | AE1: FY21 | AF1: FY22 | AG1: FY23 | AH1: FY24 | AI1: FY25 | AJ1: FY26 | AK1: FY27E | AL1: FY28E | AM1: FY29E | AN1: FY30E
A2: Fiscal Year End | D2: =DATE(2021,6,30) -> 44377 | E2: =EOMONTH(D2,-3) -> 44286 | F2: =EOMONTH(E2,-3) -> 44196 | G2: =EOMONTH(F2,-3) -> 44104 | H2: =EOMONTH(G2,-3) -> 44012 | I2: =EOMONTH(H2,-3) -> 43921 | J2: =EOMONTH(I2,-3) -> 43830 | K2: =EOMONTH(J2,-3) -> 43738 | L2: =EOMONTH(K2,-3) -> 43646 | ... AA2: =EOMONTH(Z2,-3) -> 42277 | AC2: =DATE(2019,3,31) -> 43555 | AD2: =DATE(2020,3,31) -> 43921 | AE2: =DATE(2021,3,31) -> 44286 | AF2: =DATE(2022,3,31) -> 44651 | AG2: =DATE(2023,3,31) -> 45016 | AH2: =DATE(2024,3,31) -> 45382 | AI2: =DATE(2025,3,31) -> 45747 | AJ2: =DATE(2026,3,31) -> 46112 | AK2: =DATE(2027,3,31) -> 46477 | AL2: =DATE(2028,3,31) -> 46843 | AM2: =DATE(2029,3,31) -> 47208 | AN2: =DATE(2030,3,31) -> 47573
A3: All figures in INR Mn unless stated otherwise. Historical quarters (1Q22-4Q26) and historical annual columns (FY19-FY26) link to the Raw Data tabs. 1Q27-4Q27 are left blank for a later quarterly-projection pass. FY27E-FY30E are annual projections, each chained off the preceding column in this sheet: red (#A20000) cells are hardcoded assumptions -- edit these to change the forecast; black cells are formulas.
A4: SUMMARY
A5: Total GMV | B5: Rs Mn | C5: Formula | D5: =IFERROR(D32+D61+D84,"") | E5: =IFERROR(E32+E61+E84,"") | F5: =IFERROR(F32+F61+F84,"") | G5: =IFERROR(G32+G61+G84,"") | H5: =IFERROR(H32+H61+H84,"") | I5: =IFERROR(I32+I61+I84,"") | J5: =IFERROR(J32+J61+J84,"") | K5: =IFERROR(K32+K61+K84,"") | ... W5: =IFERROR(W32+W61+W84,"") -> 52410 | AC5: =IFERROR(AC32+AC61+AC84,"") -> 0 | AD5: =IFERROR(AD32+AD61+AD84,"") -> 0 | AE5: =IFERROR(AE32+AE61+AE84,"") -> 0 | AF5: =IFERROR(AF32+AF61+AF84,"") | AG5: =IFERROR(AG32+AG61+AG84,"") | AH5: =IFERROR(AH32+AH61+AH84,"") -> 124471 | AI5: =IFERROR(AI32+AI61+AI84,"") -> 156033 | AJ5: =IFERROR(AJ32+AJ61+AJ84,"") -> 199620 | ... AN5: =IFERROR(AN32+AN61+AN84,"") -> 601648.58
A6: YoY growth | B6: % | C6: Formula | H6: =IFERROR(H5/D5-1,"") | I6: =IFERROR(I5/E5-1,"") | J6: =IFERROR(J5/F5-1,"") | K6: =IFERROR(K5/G5-1,"") | L6: =IFERROR(L5/H5-1,"") | M6: =IFERROR(M5/I5-1,"") | N6: =IFERROR(N5/J5-1,"") | O6: =IFERROR(O5/K5-1,"") | ... W6: =IFERROR(W5/S5-1,"") -> 0.27766943 | AD6: =IFERROR(AD5/AC5-1,"") | AE6: =IFERROR(AE5/AD5-1,"") | AF6: =IFERROR(AF5/AE5-1,"") | AG6: =IFERROR(AG5/AF5-1,"") | AH6: =IFERROR(AH5/AG5-1,"") | AI6: =IFERROR(AI5/AH5-1,"") -> 0.2535691 | AJ6: =IFERROR(AJ5/AI5-1,"") -> 0.27934475 | AK6: =IFERROR(AK5/AJ5-1,"") -> 0.31759087 | ... AN6: =IFERROR(AN5/AM5-1,"") -> 0.31768251
A7: Total NSV | B7: Rs Mn | C7: Formula | D7: =IFERROR(D34+D63+D86,"") | E7: =IFERROR(E34+E63+E86,"") | F7: =IFERROR(F34+F63+F86,"") | G7: =IFERROR(G34+G63+G86,"") | H7: =IFERROR(H34+H63+H86,"") | I7: =IFERROR(I34+I63+I86,"") | J7: =IFERROR(J34+J63+J86,"") | K7: =IFERROR(K34+K63+K86,"") | ... W7: =IFERROR(W34+W63+W86,"") -> 26780 | AC7: =IFERROR(AC34+AC63+AC86,"") -> 0 | AD7: =IFERROR(AD34+AD63+AD86,"") -> 0 | AE7: =IFERROR(AE34+AE63+AE86,"") -> 0 | AF7: =IFERROR(AF34+AF63+AF86,"") | AG7: =IFERROR(AG34+AG63+AG86,"") | AH7: =IFERROR(AH34+AH63+AH86,"") -> 63542 | AI7: =IFERROR(AI34+AI63+AI86,"") -> 78235 | AJ7: =IFERROR(AJ34+AJ63+AJ86,"") -> 99990 | ... AN7: =IFERROR(AN34+AN63+AN86,"") -> 299223.77
A8: NSV / GMV | B8: % | C8: Formula | D8: =IFERROR(D7/D5,"") | E8: =IFERROR(E7/E5,"") | F8: =IFERROR(F7/F5,"") | G8: =IFERROR(G7/G5,"") | H8: =IFERROR(H7/H5,"") | I8: =IFERROR(I7/I5,"") | J8: =IFERROR(J7/J5,"") | K8: =IFERROR(K7/K5,"") | ... W8: =IFERROR(W7/W5,"") -> 0.51097119 | AC8: =IFERROR(AC7/AC5,"") | AD8: =IFERROR(AD7/AD5,"") | AE8: =IFERROR(AE7/AE5,"") | AF8: =IFERROR(AF7/AF5,"") | AG8: =IFERROR(AG7/AG5,"") | AH8: =IFERROR(AH7/AH5,"") -> 0.51049642 | AI8: =IFERROR(AI7/AI5,"") -> 0.50140034 | AJ8: =IFERROR(AJ7/AJ5,"") -> 0.50090171
A9: Total Revenue | B9: Rs Mn | C9: Formula | D9: =IFERROR(D36+D65+D88,"") | E9: =IFERROR(E36+E65+E88,"") | F9: =IFERROR(F36+F65+F88,"") | G9: =IFERROR(G36+G65+G88,"") | H9: =IFERROR(H36+H65+H88,"") | I9: =IFERROR(I36+I65+I88,"") | J9: =IFERROR(J36+J65+J88,"") | K9: =IFERROR(K36+K65+K88,"") | ... W9: =IFERROR(W36+W65+W88,"") -> 26480 | AC9: =IFERROR(AC36+AC65+AC88,"") -> 0 | AD9: =IFERROR(AD36+AD65+AD88,"") -> 0 | AE9: =IFERROR(AE36+AE65+AE88,"") -> 0 | AF9: =IFERROR(AF36+AF65+AF88,"") | AG9: =IFERROR(AG36+AG65+AG88,"") | AH9: =IFERROR(AH36+AH65+AH88,"") -> 63856.26 | AI9: =IFERROR(AI36+AI65+AI88,"") -> 79498.2 | AJ9: =IFERROR(AJ36+AJ65+AJ88,"") -> 100221.8 | ... AN9: =IFERROR(AN36+AN65+AN88,"") -> 298728.44
A10: YoY growth | B10: % | C10: Formula | H10: =IFERROR(H9/D9-1,"") | I10: =IFERROR(I9/E9-1,"") | J10: =IFERROR(J9/F9-1,"") | K10: =IFERROR(K9/G9-1,"") | L10: =IFERROR(L9/H9-1,"") | M10: =IFERROR(M9/I9-1,"") | N10: =IFERROR(N9/J9-1,"") | O10: =IFERROR(O9/K9-1,"") | ... W10: =IFERROR(W9/S9-1,"") -> 0.28433959 | AD10: =IFERROR(AD9/AC9-1,"") | AE10: =IFERROR(AE9/AD9-1,"") | AF10: =IFERROR(AF9/AE9-1,"") | AG10: =IFERROR(AG9/AF9-1,"") | AH10: =IFERROR(AH9/AG9-1,"") | AI10: =IFERROR(AI9/AH9-1,"") -> 0.24495547 | AJ10: =IFERROR(AJ9/AI9-1,"") -> 0.26068012 | AK10: =IFERROR(AK9/AJ9-1,"") -> 0.31459731 | ... AN10: =IFERROR(AN9/AM9-1,"") -> 0.31376471
A11: Gross Profit | B11: Rs Mn | C11: Formula | D11: =IFERROR(D38+D67+D90,"") | E11: =IFERROR(E38+E67+E90,"") | F11: =IFERROR(F38+F67+F90,"") | G11: =IFERROR(G38+G67+G90,"") | H11: =IFERROR(H38+H67+H90,"") | I11: =IFERROR(I38+I67+I90,"") | J11: =IFERROR(J38+J67+J90,"") | K11: =IFERROR(K38+K67+K90,"") | ... W11: =IFERROR(W38+W67+W90,"") -> 11980 | AC11: =IFERROR(AC38+AC67+AC90,"") -> 0 | AD11: =IFERROR(AD38+AD67+AD90,"") -> 0 | AE11: =IFERROR(AE38+AE67+AE90,"") -> 0 | AF11: =IFERROR(AF38+AF67+AF90,"") | AG11: =IFERROR(AG38+AG67+AG90,"") | AH11: =IFERROR(AH38+AH67+AH90,"") -> 24033.4 | AI11: =IFERROR(AI38+AI67+AI90,"") -> 34366.6 | AJ11: =IFERROR(AJ38+AJ67+AJ90,"") -> 45005.3 | ... AN11: =IFERROR(AN38+AN67+AN90,"") -> 134793.16
A12: Gross margin (% of NSV) | B12: % | C12: Formula | D12: =IFERROR(D11/D7,"") | E12: =IFERROR(E11/E7,"") | F12: =IFERROR(F11/F7,"") | G12: =IFERROR(G11/G7,"") | H12: =IFERROR(H11/H7,"") | I12: =IFERROR(I11/I7,"") | J12: =IFERROR(J11/J7,"") | K12: =IFERROR(K11/K7,"") | ... W12: =IFERROR(W11/W7,"") -> 0.44734877 | AC12: =IFERROR(AC11/AC7,"") | AD12: =IFERROR(AD11/AD7,"") | AE12: =IFERROR(AE11/AE7,"") | AF12: =IFERROR(AF11/AF7,"") | AG12: =IFERROR(AG11/AG7,"") | AH12: =IFERROR(AH11/AH7,"") -> 0.37822857 | AI12: =IFERROR(AI11/AI7,"") -> 0.43927398 | AJ12: =IFERROR(AJ11/AJ7,"") -> 0.45009801
A13: EBITDA | B13: Rs Mn | C13: Formula | D13: =D99 | E13: =E99 | F13: =F99 | G13: =G99 | H13: =H99 | I13: =I99 | J13: =J99 | K13: =K99 | ... W13: =W99 -> 2220 | AC13: =AC99 | AD13: =AD99 | AE13: =AE99 | AF13: =AF99 | AG13: =AG99 | AH13: =AH99 -> 3461.51 | AI13: =AI99 -> 4739.1 | AJ13: =AJ99 -> 7953.9 | ... AN13: =AN99 -> 23548.976
A14: EBITDA margin (% of NSV) | B14: % | C14: Formula | D14: =IFERROR(D13/D7,"") | E14: =IFERROR(E13/E7,"") | F14: =IFERROR(F13/F7,"") | G14: =IFERROR(G13/G7,"") | H14: =IFERROR(H13/H7,"") | I14: =IFERROR(I13/I7,"") | J14: =IFERROR(J13/J7,"") | K14: =IFERROR(K13/K7,"") | ... W14: =IFERROR(W13/W7,"") -> 0.082897685 | AC14: =IFERROR(AC13/AC7,"") | AD14: =IFERROR(AD13/AD7,"") | AE14: =IFERROR(AE13/AE7,"") | AF14: =IFERROR(AF13/AF7,"") | AG14: =IFERROR(AG13/AG7,"") | AH14: =IFERROR(AH13/AH7,"") -> 0.054475937 | AI14: =IFERROR(AI13/AI7,"") -> 0.06057519 | AJ14: =IFERROR(AJ13/AJ7,"") -> 0.079546955
A15: PAT | B15: Rs Mn | C15: Formula | D15: =D111 | E15: =E111 | F15: =F111 | G15: =G111 | H15: =H111 | I15: =I111 | J15: =J111 | K15: =K111 | ... W15: =W111 -> 778.3 | AC15: =AC111 | AD15: =AD111 | AE15: =AE111 | AF15: =AF111 | AG15: =AG111 | AH15: =AH111 -> 437.17 | AI15: =AI111 -> 737 | AJ15: =AJ111 -> 2644.2 | ... AN15: =AN111 -> 7090.2624
A16: PAT margin (% of Revenue) | B16: % | C16: Formula | D16: =IFERROR(D15/D9,"") | E16: =IFERROR(E15/E9,"") | F16: =IFERROR(F15/F9,"") | G16: =IFERROR(G15/G9,"") | H16: =IFERROR(H15/H9,"") | I16: =IFERROR(I15/I9,"") | J16: =IFERROR(J15/J9,"") | K16: =IFERROR(K15/K9,"") | ... W16: =IFERROR(W15/W9,"") -> 0.029391994 | AC16: =IFERROR(AC15/AC9,"") | AD16: =IFERROR(AD15/AD9,"") | AE16: =IFERROR(AE15/AE9,"") | AF16: =IFERROR(AF15/AF9,"") | AG16: =IFERROR(AG15/AG9,"") | AH16: =IFERROR(AH15/AH9,"") -> 0.0068461573 | AI16: =IFERROR(AI15/AI9,"") -> 0.0092706502 | AJ16: =IFERROR(AJ15/AJ9,"") -> 0.026383481
A17: EPS (diluted) | B17: Rs | C17: Formula | D17: =D113 -> 0.07 | E17: =E113 -> 0.03 | F17: =F113 -> 0.6 | G17: =G113 -> 0.18 | H17: =H113 -> 0 | I17: =I113 -> 0.01 | J17: =J113 -> 0.03 | K17: =K113 -> 0.01 | ... W17: =W113 -> 0.27 | AC17: =AC113 -> -17.7 | AD17: =AD113 -> -11.63 | AE17: =AE113 -> 40.07 | AF17: =AF113 -> 0.87 | AG17: =AG113 -> 0.07 | AH17: =AH113 -> 0.11 | AI17: =AI113 -> 0.23 | AJ17: =AJ113 -> 0.7 | ... AN17: =AN113 -> 2.4886846
A19: Segment mix (% of Total GMV)
A20: Beauty | B20: % | C20: Formula | D20: =IFERROR(D32/D5,"") | E20: =IFERROR(E32/E5,"") | F20: =IFERROR(F32/F5,"") | G20: =IFERROR(G32/G5,"") | H20: =IFERROR(H32/H5,"") | I20: =IFERROR(I32/I5,"") | J20: =IFERROR(J32/J5,"") | K20: =IFERROR(K32/K5,"") | ... W20: =IFERROR(W32/W5,"") -> 0.74260637 | AC20: =IFERROR(AC32/AC5,"") | AD20: =IFERROR(AD32/AD5,"") | AE20: =IFERROR(AE32/AE5,"") | AF20: =IFERROR(AF32/AF5,"") | AG20: =IFERROR(AG32/AG5,"") | AH20: =IFERROR(AH32/AH5,"") -> 0.72750279 | AI20: =IFERROR(AI32/AI5,"") -> 0.75459038 | AJ20: =IFERROR(AJ32/AJ5,"") -> 0.74907324 | ... AN20: =IFERROR(AN32/AN5,"") -> 0.73603931
A21: Fashion | B21: % | C21: Formula | D21: =IFERROR(D61/D5,"") | E21: =IFERROR(E61/E5,"") | F21: =IFERROR(F61/F5,"") | G21: =IFERROR(G61/G5,"") | H21: =IFERROR(H61/H5,"") | I21: =IFERROR(I61/I5,"") | J21: =IFERROR(J61/J5,"") | K21: =IFERROR(K61/K5,"") | ... W21: =IFERROR(W61/W5,"") -> 0.25453158 | AC21: =IFERROR(AC61/AC5,"") | AD21: =IFERROR(AD61/AD5,"") | AE21: =IFERROR(AE61/AE5,"") | AF21: =IFERROR(AF61/AF5,"") | AG21: =IFERROR(AG61/AG5,"") | AH21: =IFERROR(AH61/AH5,"") -> 0.27199107 | AI21: =IFERROR(AI61/AI5,"") -> 0.24381381 | AJ21: =IFERROR(AJ61/AJ5,"") -> 0.24817153 | ... AN21: =IFERROR(AN61/AN5,"") -> 0.26134977
A22: New Business | B22: % | C22: Formula | D22: =IFERROR(D84/D5,"") | E22: =IFERROR(E84/E5,"") | F22: =IFERROR(F84/F5,"") | G22: =IFERROR(G84/G5,"") | H22: =IFERROR(H84/H5,"") | I22: =IFERROR(I84/I5,"") | J22: =IFERROR(J84/J5,"") | K22: =IFERROR(K84/K5,"") | ... W22: =IFERROR(W84/W5,"") -> 0.0028620492 | AC22: =IFERROR(AC84/AC5,"") | AD22: =IFERROR(AD84/AD5,"") | AE22: =IFERROR(AE84/AE5,"") | AF22: =IFERROR(AF84/AF5,"") | AG22: =IFERROR(AG84/AG5,"") | AH22: =IFERROR(AH84/AH5,"") -> 0.00050614199 | AI22: =IFERROR(AI84/AI5,"") -> 0.0015958163 | AJ22: =IFERROR(AJ84/AJ5,"") -> 0.0027552349 | ... AN22: =IFERROR(AN84/AN5,"") -> 0.0026109178
A24: BEAUTY (incl. SuperStore)
A25: Definition: BPC (online + offline) + Superstore by Nykaa + Nykaa Man Grooming + House of Nykaa owned brands. NOTE: AUTC/Orders/AOV here are sourced from the deck's 'BPC Vertical' KPI table, which is a narrower scope than the GMV/NSV/Revenue lines below (GMV includes SuperStore, BPC Vertical orders don't) -- see the equivalent caveat on the Raw Data - Ops KPIs tab. AOV = GMV/Orders here is therefore a blended incl-SuperStore figure, not Nykaa's own reported BPC AOV.
A26: Annual transacting customers (AUTC) | B26: mn | C26: Link: Raw Data - Ops KPIs | D26: ='Raw Data - Ops KPIs'!D35 -> 6.5 | E26: ='Raw Data - Ops KPIs'!E35 -> 7 | F26: ='Raw Data - Ops KPIs'!F35 -> 7.5 | G26: ='Raw Data - Ops KPIs'!G35 -> 8 | H26: ='Raw Data - Ops KPIs'!H35 -> 8.6 | I26: ='Raw Data - Ops KPIs'!I35 -> 9.1 | J26: ='Raw Data - Ops KPIs'!J35 -> 9.6 | K26: ='Raw Data - Ops KPIs'!K35 -> 10 | ... W26: ='Raw Data - Ops KPIs'!W35 -> 19.7 | AF26: ='Raw Data - Ops KPIs'!AF35 -> 8 | AG26: ='Raw Data - Ops KPIs'!AG35 -> 10 | AH26: ='Raw Data - Ops KPIs'!AH35 -> 12.4 | AI26: ='Raw Data - Ops KPIs'!AI35 -> 15.8 | AJ26: ='Raw Data - Ops KPIs'!AJ35 -> 19.7 | AK26: =AJ26*(1+AK27) -> 24.5659 | AL26: =AK26*(1+AL27) -> 30.633677 | AM26: =AL26*(1+AM27) -> 38.200196 | AN26: =AM26*(1+AN27) -> 47.635644
A27: YoY growth | B27: % | C27: Assumption (edit me) | H27: =IFERROR(H26/D26-1,"") -> 0.32307692 | I27: =IFERROR(I26/E26-1,"") -> 0.3 | J27: =IFERROR(J26/F26-1,"") -> 0.28 | K27: =IFERROR(K26/G26-1,"") -> 0.25 | L27: =IFERROR(L26/H26-1,"") -> 0.26744186 | M27: =IFERROR(M26/I26-1,"") -> 0.17582418 | N27: =IFERROR(N26/J26-1,"") -> 0.21875 | O27: =IFERROR(O26/K26-1,"") -> 0.24 | ... W27: =IFERROR(W26/S26-1,"") -> 0.24683544 | AD27: =IFERROR(AD26/AC26-1,"") | AE27: =IFERROR(AE26/AD26-1,"") | AF27: =IFERROR(AF26/AE26-1,"") | AG27: =IFERROR(AG26/AF26-1,"") -> 0.25 | AH27: =IFERROR(AH26/AG26-1,"") -> 0.24 | AI27: =IFERROR(AI26/AH26-1,"") -> 0.27419355 | AJ27: =IFERROR(AJ26/AI26-1,"") -> 0.24683544 | AK27: 0.247 | AL27: 0.247 | AM27: 0.247 | AN27: 0.247
A28: Number of orders | B28: mn | C28: Link: Raw Data - Ops KPIs | D28: ='Raw Data - Ops KPIs'!D37 -> 5.8 | E28: ='Raw Data - Ops KPIs'!E37 -> 6 | F28: ='Raw Data - Ops KPIs'!F37 -> 7.5 | G28: ='Raw Data - Ops KPIs'!G37 -> 7.2 | H28: ='Raw Data - Ops KPIs'!H37 -> 8.1 | I28: ='Raw Data - Ops KPIs'!I37 -> 8.4 | J28: ='Raw Data - Ops KPIs'!J37 -> 9.5 | K28: ='Raw Data - Ops KPIs'!K37 -> 8.8 | ... W28: ='Raw Data - Ops KPIs'!W37 -> 17.5 | AF28: ='Raw Data - Ops KPIs'!AF37 -> 26.5 | AG28: ='Raw Data - Ops KPIs'!AG37 -> 34.8 | AH28: ='Raw Data - Ops KPIs'!AH37 -> 43.7 | AI28: ='Raw Data - Ops KPIs'!AI37 -> 54.5 | AJ28: ='Raw Data - Ops KPIs'!AJ37 -> 65.8 | AK28: =AK26*AK29 -> 82.050106 | AL28: =AL26*AL29 -> 102.31648 | AM28: =AM26*AM29 -> 127.58865 | AN28: =AN26*AN29 -> 159.10305
A29: Average order frequency | B29: x | C29: Assumption (edit me) | D29: =IFERROR(D28/D26,"") -> 0.89230769 | E29: =IFERROR(E28/E26,"") -> 0.85714286 | F29: =IFERROR(F28/F26,"") -> 1 | G29: =IFERROR(G28/G26,"") -> 0.9 | H29: =IFERROR(H28/H26,"") -> 0.94186047 | I29: =IFERROR(I28/I26,"") -> 0.92307692 | J29: =IFERROR(J28/J26,"") -> 0.98958333 | K29: =IFERROR(K28/K26,"") -> 0.88 | ... W29: =IFERROR(W28/W26,"") -> 0.88832487 | AC29: =IFERROR(AC28/AC26,"") | AD29: =IFERROR(AD28/AD26,"") | AE29: =IFERROR(AE28/AE26,"") | AF29: =IFERROR(AF28/AF26,"") -> 3.3125 | AG29: =IFERROR(AG28/AG26,"") -> 3.48 | AH29: =IFERROR(AH28/AH26,"") -> 3.5241935 | AI29: =IFERROR(AI28/AI26,"") -> 3.4493671 | AJ29: =IFERROR(AJ28/AJ26,"") -> 3.3401015 | AK29: 3.34 | AL29: 3.34 | AM29: 3.34 | AN29: 3.34
A30: Average order value | B30: Rs | C30: Formula | D30: =IFERROR(D32/D28,"") -> 0 | E30: =IFERROR(E32/E28,"") -> 0 | F30: =IFERROR(F32/F28,"") -> 0 | G30: =IFERROR(G32/G28,"") -> 0 | H30: =IFERROR(H32/H28,"") -> 0 | I30: =IFERROR(I32/I28,"") -> 0 | J30: =IFERROR(J32/J28,"") -> 0 | K30: =IFERROR(K32/K28,"") -> 0 | ... W30: =IFERROR(W32/W28,"") -> 2224 | AC30: =IFERROR(AC32/AC28,"") | AD30: =IFERROR(AD32/AD28,"") | AE30: =IFERROR(AE32/AE28,"") | AF30: =IFERROR(AF32/AF28,"") | AG30: =IFERROR(AG32/AG28,"") | AH30: =IFERROR(AH32/AH28,"") -> 2072.151 | AI30: =IFERROR(AI32/AI28,"") -> 2160.3853 | AJ30: =IFERROR(AJ32/AJ28,"") -> 2272.4924 | AK30: =AJ30*(1+AK31) -> 2390.662 | AL30: =AK30*(1+AL31) -> 2514.9764 | AM30: =AL30*(1+AM31) -> 2645.7552 | AN30: =AM30*(1+AN31) -> 2783.3345
A31: YoY growth | B31: % | C31: Assumption (edit me) | AK31: 0.052 | AL31: 0.052 | AM31: 0.052 | AN31: 0.052
A32: GMV | B32: Rs Mn | C32: Link: Raw Data - Ops KPIs | D32: ='Raw Data - Ops KPIs'!D40 -> 0 | E32: ='Raw Data - Ops KPIs'!E40 -> 0 | F32: ='Raw Data - Ops KPIs'!F40 -> 0 | G32: ='Raw Data - Ops KPIs'!G40 -> 0 | H32: ='Raw Data - Ops KPIs'!H40 -> 0 | I32: ='Raw Data - Ops KPIs'!I40 -> 0 | J32: ='Raw Data - Ops KPIs'!J40 -> 0 | K32: ='Raw Data - Ops KPIs'!K40 -> 0 | ... W32: ='Raw Data - Ops KPIs'!W40 -> 38920 | AF32: ='Raw Data - Ops KPIs'!AF40 | AG32: ='Raw Data - Ops KPIs'!AG40 | AH32: ='Raw Data - Ops KPIs'!AH40 -> 90553 | AI32: ='Raw Data - Ops KPIs'!AI40 -> 117741 | AJ32: ='Raw Data - Ops KPIs'!AJ40 -> 149530 | AK32: =AK28*AK30 -> 196154.07 | AL32: =AL28*AL30 -> 257323.54 | AM32: =AM28*AM30 -> 337568.34 | AN32: =AN28*AN30 -> 442837.01
A33: YoY growth | B33: % | C33: Formula | H33: =IFERROR(H32/D32-1,"") | I33: =IFERROR(I32/E32-1,"") | J33: =IFERROR(J32/F32-1,"") | K33: =IFERROR(K32/G32-1,"") | L33: =IFERROR(L32/H32-1,"") | M33: =IFERROR(M32/I32-1,"") | N33: =IFERROR(N32/J32-1,"") | O33: =IFERROR(O32/K32-1,"") | ... W33: =IFERROR(W32/S32-1,"") -> 0.27272727 | AD33: =IFERROR(AD32/AC32-1,"") | AE33: =IFERROR(AE32/AD32-1,"") | AF33: =IFERROR(AF32/AE32-1,"") | AG33: =IFERROR(AG32/AF32-1,"") | AH33: =IFERROR(AH32/AG32-1,"") | AI33: =IFERROR(AI32/AH32-1,"") -> 0.30024406 | AJ33: =IFERROR(AJ32/AI32-1,"") -> 0.26999091 | AK33: =IFERROR(AK32/AJ32-1,"") -> 0.31180413 | ... AN33: =IFERROR(AN32/AM32-1,"") -> 0.311844
A34: NSV | B34: Rs Mn | C34: Link: Raw Data - Ops KPIs | D34: ='Raw Data - Ops KPIs'!D43 -> 0 | E34: ='Raw Data - Ops KPIs'!E43 -> 0 | F34: ='Raw Data - Ops KPIs'!F43 -> 0 | G34: ='Raw Data - Ops KPIs'!G43 -> 0 | H34: ='Raw Data - Ops KPIs'!H43 -> 0 | I34: ='Raw Data - Ops KPIs'!I43 -> 0 | J34: ='Raw Data - Ops KPIs'!J43 -> 0 | K34: ='Raw Data - Ops KPIs'!K43 -> 0 | ... W34: ='Raw Data - Ops KPIs'!W43 -> 22690 | AF34: ='Raw Data - Ops KPIs'!AF43 | AG34: ='Raw Data - Ops KPIs'!AG43 | AH34: ='Raw Data - Ops KPIs'!AH43 -> 53620 | AI34: ='Raw Data - Ops KPIs'!AI43 -> 66743 | AJ34: ='Raw Data - Ops KPIs'!AJ43 -> 85050 | AK34: =AK32*AK35 -> 111611.67 | AL34: =AL32*AL35 -> 146417.09 | AM34: =AM32*AM35 -> 192076.39 | AN34: =AN32*AN35 -> 251974.26
A35: NSV / GMV | B35: % | C35: Assumption (edit me) | D35: =IFERROR(D34/D32,"") | E35: =IFERROR(E34/E32,"") | F35: =IFERROR(F34/F32,"") | G35: =IFERROR(G34/G32,"") | H35: =IFERROR(H34/H32,"") | I35: =IFERROR(I34/I32,"") | J35: =IFERROR(J34/J32,"") | K35: =IFERROR(K34/K32,"") | ... W35: =IFERROR(W34/W32,"") -> 0.58299075 | AC35: =IFERROR(AC34/AC32,"") | AD35: =IFERROR(AD34/AD32,"") | AE35: =IFERROR(AE34/AE32,"") | AF35: =IFERROR(AF34/AF32,"") | AG35: =IFERROR(AG34/AG32,"") | AH35: =IFERROR(AH34/AH32,"") -> 0.59213941 | AI35: =IFERROR(AI34/AI32,"") -> 0.56686286 | AJ35: =IFERROR(AJ34/AJ32,"") -> 0.56878218 | AK35: 0.569 | AL35: 0.569 | AM35: 0.569 | AN35: 0.569
A36: Revenue | B36: Rs Mn | C36: Link: Raw Data - Ops KPIs | D36: ='Raw Data - Ops KPIs'!D45 -> 0 | E36: ='Raw Data - Ops KPIs'!E45 -> 0 | F36: ='Raw Data - Ops KPIs'!F45 -> 0 | G36: ='Raw Data - Ops KPIs'!G45 -> 0 | H36: ='Raw Data - Ops KPIs'!H45 -> 0 | I36: ='Raw Data - Ops KPIs'!I45 -> 0 | J36: ='Raw Data - Ops KPIs'!J45 -> 0 | K36: ='Raw Data - Ops KPIs'!K45 -> 0 | ... W36: ='Raw Data - Ops KPIs'!W45 -> 24100 | AF36: ='Raw Data - Ops KPIs'!AF45 | AG36: ='Raw Data - Ops KPIs'!AG45 | AH36: ='Raw Data - Ops KPIs'!AH45 -> 44401 | AI36: ='Raw Data - Ops KPIs'!AI45 -> 72515 | AJ36: ='Raw Data - Ops KPIs'!AJ45 -> 91390 | AK36: =AK34*AK37 -> 119982.54 | AL36: =AL34*AL37 -> 157398.38 | AM36: =AM34*AM37 -> 206482.12 | AN36: =AN34*AN37 -> 270872.33
A37: Revenue / NSV | B37: % | C37: Assumption (edit me) | D37: =IFERROR(D36/D34,"") | E37: =IFERROR(E36/E34,"") | F37: =IFERROR(F36/F34,"") | G37: =IFERROR(G36/G34,"") | H37: =IFERROR(H36/H34,"") | I37: =IFERROR(I36/I34,"") | J37: =IFERROR(J36/J34,"") | K37: =IFERROR(K36/K34,"") | ... W37: =IFERROR(W36/W34,"") -> 1.0621419 | AC37: =IFERROR(AC36/AC34,"") | AD37: =IFERROR(AD36/AD34,"") | AE37: =IFERROR(AE36/AE34,"") | AF37: =IFERROR(AF36/AF34,"") | AG37: =IFERROR(AG36/AG34,"") | AH37: =IFERROR(AH36/AH34,"") -> 0.82806789 | AI37: =IFERROR(AI36/AI34,"") -> 1.086481 | AJ37: =IFERROR(AJ36/AJ34,"") -> 1.0745444 | AK37: 1.075 | AL37: 1.075 | AM37: 1.075 | AN37: 1.075
A38: Gross profit | B38: Rs Mn | C38: Link: Raw Data - Ops KPIs | D38: ='Raw Data - Ops KPIs'!D47 -> 0 | E38: ='Raw Data - Ops KPIs'!E47 -> 0 | F38: ='Raw Data - Ops KPIs'!F47 -> 0 | G38: ='Raw Data - Ops KPIs'!G47 -> 0 | H38: ='Raw Data - Ops KPIs'!H47 -> 0 | I38: ='Raw Data - Ops KPIs'!I47 -> 0 | J38: ='Raw Data - Ops KPIs'!J47 -> 0 | K38: ='Raw Data - Ops KPIs'!K47 -> 0 | ... W38: ='Raw Data - Ops KPIs'!W47 -> 10130 | AF38: ='Raw Data - Ops KPIs'!AF47 | AG38: ='Raw Data - Ops KPIs'!AG47 | AH38: ='Raw Data - Ops KPIs'!AH47 -> 17490 | AI38: ='Raw Data - Ops KPIs'!AI47 -> 29121 | AJ38: ='Raw Data - Ops KPIs'!AJ47 -> 38010 | AK38: =AK34*AK39 -> 49890.415 | AL38: =AL34*AL39 -> 65448.441 | AM38: =AM34*AM39 -> 85858.145 | AN38: =AN34*AN39 -> 112632.49
A39: Gross margin (% of NSV) | B39: % | C39: Assumption (edit me) | D39: =IFERROR(D38/D34,"") | E39: =IFERROR(E38/E34,"") | F39: =IFERROR(F38/F34,"") | G39: =IFERROR(G38/G34,"") | H39: =IFERROR(H38/H34,"") | I39: =IFERROR(I38/I34,"") | J39: =IFERROR(J38/J34,"") | K39: =IFERROR(K38/K34,"") | ... W39: =IFERROR(W38/W34,"") -> 0.44645218 | AC39: =IFERROR(AC38/AC34,"") | AD39: =IFERROR(AD38/AD34,"") | AE39: =IFERROR(AE38/AE34,"") | AF39: =IFERROR(AF38/AF34,"") | AG39: =IFERROR(AG38/AG34,"") | AH39: =IFERROR(AH38/AH34,"") -> 0.32618426 | AI39: =IFERROR(AI38/AI34,"") -> 0.43631542 | AJ39: =IFERROR(AJ38/AJ34,"") -> 0.44691358 | AK39: 0.447 | AL39: 0.447 | AM39: 0.447 | AN39: 0.447
A40: Fulfilment cost | B40: Rs Mn | C40: Link: Raw Data - Ops KPIs | D40: ='Raw Data - Ops KPIs'!D49 -> 0 | E40: ='Raw Data - Ops KPIs'!E49 -> 0 | F40: ='Raw Data - Ops KPIs'!F49 -> 0 | G40: ='Raw Data - Ops KPIs'!G49 -> 0 | H40: ='Raw Data - Ops KPIs'!H49 -> 0 | I40: ='Raw Data - Ops KPIs'!I49 -> 0 | J40: ='Raw Data - Ops KPIs'!J49 -> 0 | K40: ='Raw Data - Ops KPIs'!K49 -> 0 | ... W40: ='Raw Data - Ops KPIs'!W49 -> 2150 | AF40: ='Raw Data - Ops KPIs'!AF49 | AG40: ='Raw Data - Ops KPIs'!AG49 | AH40: ='Raw Data - Ops KPIs'!AH49 -> 3790 | AI40: ='Raw Data - Ops KPIs'!AI49 -> 6284 | AJ40: ='Raw Data - Ops KPIs'!AJ49 -> 7940 | AK40: =AK34*AK41 -> 10379.885 | AL40: =AL34*AL41 -> 13616.79 | AM40: =AM34*AM41 -> 17863.104 | AN40: =AN34*AN41 -> 23433.606
A41: Fulfilment (% of NSV) | B41: % | C41: Assumption (edit me) | D41: =IFERROR(D40/D34,"") | E41: =IFERROR(E40/E34,"") | F41: =IFERROR(F40/F34,"") | G41: =IFERROR(G40/G34,"") | H41: =IFERROR(H40/H34,"") | I41: =IFERROR(I40/I34,"") | J41: =IFERROR(J40/J34,"") | K41: =IFERROR(K40/K34,"") | ... W41: =IFERROR(W40/W34,"") -> 0.094755399 | AC41: =IFERROR(AC40/AC34,"") | AD41: =IFERROR(AD40/AD34,"") | AE41: =IFERROR(AE40/AE34,"") | AF41: =IFERROR(AF40/AF34,"") | AG41: =IFERROR(AG40/AG34,"") | AH41: =IFERROR(AH40/AH34,"") -> 0.070682581 | AI41: =IFERROR(AI40/AI34,"") -> 0.094152196 | AJ41: =IFERROR(AJ40/AJ34,"") -> 0.093356849 | AK41: 0.093 | AL41: 0.093 | AM41: 0.093 | AN41: 0.093
A42: Marketing & S&D expense (combined) | B42: Rs Mn | C42: Formula | D42: =IF(AND(D44="",D45=""),"",IF(D44="",0,D44)+IF(D45="",0,D45)) -> 0 | E42: =IF(AND(E44="",E45=""),"",IF(E44="",0,E44)+IF(E45="",0,E45)) -> 0 | F42: =IF(AND(F44="",F45=""),"",IF(F44="",0,F44)+IF(F45="",0,F45)) -> 0 | G42: =IF(AND(G44="",G45=""),"",IF(G44="",0,G44)+IF(G45="",0,G45)) -> 0 | H42: =IF(AND(H44="",H45=""),"",IF(H44="",0,H44)+IF(H45="",0,H45)) -> 0 | I42: =IF(AND(I44="",I45=""),"",IF(I44="",0,I44)+IF(I45="",0,I45)) -> 0 | J42: =IF(AND(J44="",J45=""),"",IF(J44="",0,J44)+IF(J45="",0,J45)) -> 0 | K42: =IF(AND(K44="",K45=""),"",IF(K44="",0,K44)+IF(K45="",0,K45)) -> 0 | ... W42: =IF(AND(W44="",W45=""),"",IF(W44="",0,W44)+IF(W45="",0,W45)) -> 2780 | AC42: =IF(AND(AC44="",AC45=""),"",IF(AC44="",0,AC44)+IF(AC45="",0,AC45)) | AD42: =IF(AND(AD44="",AD45=""),"",IF(AD44="",0,AD44)+IF(AD45="",0,AD45)) | AE42: =IF(AND(AE44="",AE45=""),"",IF(AE44="",0,AE44)+IF(AE45="",0,AE45)) | AF42: =IF(AND(AF44="",AF45=""),"",IF(AF44="",0,AF44)+IF(AF45="",0,AF45)) | AG42: =IF(AND(AG44="",AG45=""),"",IF(AG44="",0,AG44)+IF(AG45="",0,AG45)) | AH42: =IF(AND(AH44="",AH45=""),"",IF(AH44="",0,AH44)+IF(AH45="",0,AH45)) -> 4665 | AI42: =IF(AND(AI44="",AI45=""),"",IF(AI44="",0,AI44)+IF(AI45="",0,AI45)) -> 8131 | AJ42: =IF(AND(AJ44="",AJ45=""),"",IF(AJ44="",0,AJ44)+IF(AJ45="",0,AJ45)) -> 10910 | AK42: =AK34*AK43 -> 14286.293 | AL42: =AL34*AL43 -> 18741.388 | AM42: =AM34*AM43 -> 24585.778 | AN42: =AN34*AN43 -> 32252.705
...

Sheet Raw Data - financials
A1: INR Mn | B1: Unit | C1: Source | D1: 1Q22 | E1: 2Q22 | F1: 3Q22 | G1: 4Q22 | H1: 1Q23 | I1: 2Q23 | J1: 3Q23 | K1: 4Q23 | L1: 1Q24 | M1: 2Q24 | N1: 3Q24 | O1: 4Q24 | P1: 1Q25 | Q1: 2Q25 | R1: 3Q25 | S1: 4Q25 | T1: 1Q26 | U1: 2Q26 | V1: 3Q26 | W1: 4Q26 | X1: 1Q27 | Y1: 2Q27 | Z1: 3Q27 | AA1: 4Q27 | AC1: FY19 | AD1: FY20 | AE1: FY21 | AF1: FY22 | AG1: FY23 | AH1: FY24 | AI1: FY25 | AJ1: FY26
A2: Fiscal Year End | D2: =EOMONTH(E2,-3) -> 44377 | E2: =EOMONTH(F2,-3) -> 44469 | F2: =EOMONTH(G2,-3) -> 44561 | G2: =EOMONTH(H2,-3) -> 44651 | H2: =EOMONTH(I2,-3) -> 44742 | I2: =EOMONTH(J2,-3) -> 44834 | J2: =EOMONTH(K2,-3) -> 44926 | K2: =EOMONTH(L2,-3) -> 45016 | ... V2: =EOMONTH(W2,-3) -> 46022 | W2: 46112 | X2: =EOMONTH(W2,3) -> 46203 | Y2: =EOMONTH(X2,3) -> 46295 | Z2: =EOMONTH(Y2,3) -> 46387 | AA2: =EOMONTH(Z2,3) -> 46477 | AC2: 43555 | AD2: 43921 | AE2: 44286 | AF2: 44651 | AG2: 45016 | AH2: 45382 | AI2: 45747 | AJ2: 46112
A3: All figures in INR Mn unless stated otherwise.
A4: PROFIT & LOSS (CONSOLIDATED)
A5: Revenue from operations | B5: INR Mn | C5: Company filings | D5: 8169.91 | E5: 8852.64 | F5: 10983.6 | G5: 9733.2 | H5: 11484.21 | I5: 12308.29 | J5: 14628.26 | K5: 13017.24 | L5: 14218.24 | M5: 15070.24 | N5: 17887.98 | O5: 16679.8 | P5: 17461.1 | Q5: 18747.4 | R5: 22672.1 | S5: 20617.6 | T5: 21549.4 | U5: 23459.8 | V5: 28732.6 | W5: 26481.7 | AC5: 11113.94 | AD5: 17675.33 | AE5: 24408.96 | AF5: 37739.35 | AG5: 51438 | AH5: 63856.26 | AI5: 79498.2 | AJ5: 100223.5
A6: Other income | B6: INR Mn | C6: Company filings | D6: 47.22 | E6: 51.98 | F6: 59.13 | G6: 111.39 | H6: 83.63 | I6: 64.76 | J6: 56.36 | K6: 97.38 | L6: 67.21 | M6: 85.73 | N6: 75.84 | O6: 70.63 | P6: 73.3 | Q6: 54.5 | R6: 55.3 | S6: 89.5 | T6: 93.3 | U6: 80.3 | V6: 62.6 | W6: 91.5 | AC6: 49.88 | AD6: 103.17 | AE6: 117.41 | AF6: 269.72 | AG6: 302.13 | AH6: 299.42 | AI6: 272.6 | AJ6: 327.7
A7: Total Income | B7: INR Mn | D7: =SUM(D5:D6) -> 8217.13 | E7: =SUM(E5:E6) -> 8904.62 | F7: =SUM(F5:F6) -> 11042.73 | G7: =SUM(G5:G6) -> 9844.59 | H7: =SUM(H5:H6) -> 11567.84 | I7: =SUM(I5:I6) -> 12373.05 | J7: =SUM(J5:J6) -> 14684.62 | K7: =SUM(K5:K6) -> 13114.62 | ... W7: =SUM(W5:W6) -> 26573.2 | AC7: =SUM(AC5:AC6) -> 11163.82 | AD7: =SUM(AD5:AD6) -> 17778.5 | AE7: =SUM(AE5:AE6) -> 24526.37 | AF7: =SUM(AF5:AF6) -> 38009.07 | AG7: =SUM(AG5:AG6) -> 51740.13 | AH7: =SUM(AH5:AH6) -> 64155.68 | AI7: =SUM(AI5:AI6) -> 79770.8 | AJ7: =SUM(AJ5:AJ6) -> 100551.2
A9: Expenses
A10: Cost of material consumed | B10: INR Mn | C10: Company filings | D10: 229.37 | E10: 179.32 | F10: 176.56 | G10: 257.87 | H10: 232.97 | I10: 222.51 | J10: 166.08 | K10: 972.77 | L10: 186 | M10: 155.06 | N10: 235.19 | O10: 74.87 | P10: 25.9 | Q10: 14.5 | R10: 27.8 | S10: 12.8 | T10: 33.3 | U10: 3.4 | V10: 22.1 | W10: 87.3 | AC10: 2.41 | AD10: 173.43 | AE10: 382.41 | AF10: 843.12 | AG10: 1594.33 | AH10: 651.13 | AI10: 81 | AJ10: 146.1
A11: Purchase of traded goods | B11: INR Mn | C11: Company filings | D11: 5509.42 | E11: 4848.33 | F11: 6902.15 | G11: 6643.6 | H11: 7415.45 | I11: 5858.02 | J11: 9188.98 | K11: 6017.46 | L11: 9781.98 | M11: 5530.25 | N11: 12322.52 | O11: 10182.01 | P11: 11718 | Q11: 10860.8 | R11: 12849.6 | S11: 11402.3 | T11: 14444.5 | U11: 11965.3 | V11: 15047.7 | W11: 15728.3 | AC11: 7852.43 | AD11: 11787.46 | AE11: 14956.06 | AF11: 24078.31 | AG11: 28479.91 | AH11: 37816.75 | AI11: 46830.8 | AJ11: 57185.8
A12: Changes in inventories of finished goods and stock-in-trade | B12: INR Mn | C12: Company filings | D12: -885.47 | E12: 42.57 | F12: -1182.69 | G12: -1420.88 | H12: -1263 | I12: 650.38 | J12: -1073.5 | K12: 268.69 | L12: -1935.99 | M12: 2888.69 | N12: -2277.21 | O12: -679.51 | P12: -1842.6 | Q12: -338.1 | R12: -116.7 | S12: 112.3 | T12: -2543.5 | U12: 955.7 | V12: 688 | W12: -1366.8 | AC12: -1252.07 | AD12: -1818.84 | AE12: -460.22 | AF12: -3621.28 | AG12: -1417.43 | AH12: -2004.02 | AI12: -2185.2 | AJ12: -2266.6
A13: Employee benefits expense | B13: INR Mn | C13: Company filings | D13: 726.05 | E13: 694.01 | F13: 933.21 | G13: 908 | H13: 1147.09 | I13: 1217.61 | J13: 1279.16 | K13: 1273.31 | L13: 1385.76 | M13: 1363.2 | N13: 1479.3 | O13: 1420.75 | P13: 1558.6 | Q13: 1614.9 | R13: 1746 | S13: 1741.2 | T13: 1820.2 | U13: 1827.7 | V13: 2029 | W13: 2038.4 | AC13: 1172.96 | AD13: 1956.13 | AE13: 2836.47 | AF13: 3259.39 | AG13: 4917.17 | AH13: 5649.01 | AI13: 6660.7 | AJ13: 7715.3
A14: Finance costs | B14: INR Mn | C14: Company filings | D14: 90.14 | E14: 113.49 | F14: 127.9 | G14: 133.58 | H14: 150.63 | I14: 203.56 | J14: 204.25 | K14: 187.61 | L14: 185.48 | M14: 213.09 | N14: 218.41 | O14: 211.34 | P14: 213.1 | Q14: 242.3 | R14: 319.3 | S14: 298.5 | T14: 301.6 | U14: 314.7 | V14: 291.6 | W14: 263.3 | AC14: 263.42 | AD14: 442.93 | AE14: 307.01 | AF14: 465.11 | AG14: 746.05 | AH14: 828.32 | AI14: 1073.2 | AJ14: 1171.2
A15: Depreciation and amortisation expense | B15: INR Mn | C15: Company filings | D15: 194.97 | E15: 213.08 | F15: 251.24 | G15: 304.84 | H15: 310.12 | I15: 385.02 | J15: 507 | K15: 530.42 | L15: 519.2 | M15: 546.36 | N15: 580.28 | O15: 596.49 | P15: 600.6 | Q15: 636.2 | R15: 698.2 | S15: 729 | T15: 761.4 | U15: 790.9 | V15: 808.8 | W15: 842.2 | AC15: 308.76 | AD15: 595.09 | AE15: 671.28 | AF15: 964.13 | AG15: 1732.56 | AH15: 2242.33 | AI15: 2664 | AJ15: 3203.3
A16: Other expenses | B16: INR Mn | C16: Company filings | D16: 2321.16 | E16: 2800.17 | F16: 3464.6 | G16: 2959.42 | H16: 3491.18 | I16: 3748.4 | J16: 4285.94 | K16: 3778.07 | L16: 4065.83 | M16: 4326.75 | N16: 5140.44 | O16: 4748.86 | P16: 5040 | Q16: 5558.7 | R16: 6757.6 | S16: 6015.5 | T16: 6388.1 | U16: 7118.2 | V16: 8648.2 | W16: 7765.3 | AC16: 3133.11 | AD16: 4766.6 | AE16: 5079.98 | AF16: 11547.23 | AG16: 15303.59 | AH16: 18281.89 | AI16: 23371.8 | AJ16: 29919.8
A17: Total Expenses | B17: INR Mn | D17: =SUM(D10:D16) -> 8185.64 | E17: =SUM(E10:E16) -> 8890.97 | F17: =SUM(F10:F16) -> 10672.97 | G17: =SUM(G10:G16) -> 9786.43 | H17: =SUM(H10:H16) -> 11484.44 | I17: =SUM(I10:I16) -> 12285.5 | J17: =SUM(J10:J16) -> 14557.91 | K17: =SUM(K10:K16) -> 13028.33 | ... W17: =SUM(W10:W16) -> 25358 | AC17: =SUM(AC10:AC16) -> 11481.02 | AD17: =SUM(AD10:AD16) -> 17902.8 | AE17: =SUM(AE10:AE16) -> 23772.99 | AF17: =SUM(AF10:AF16) -> 37536.01 | AG17: =SUM(AG10:AG16) -> 51356.18 | AH17: =SUM(AH10:AH16) -> 63465.41 | AI17: =SUM(AI10:AI16) -> 78496.3 | AJ17: =SUM(AJ10:AJ16) -> 97074.9
A19: Profit Before Exceptional Items and Tax | B19: INR Mn | D19: =D7-D17 -> 31.49 | E19: =E7-E17 -> 13.65 | F19: =F7-F17 -> 369.76 | G19: =G7-G17 -> 58.16 | H19: =H7-H17 -> 83.4 | I19: =I7-I17 -> 87.55 | J19: =J7-J17 -> 126.71 | K19: =K7-K17 -> 86.29 | ... W19: =W7-W17 -> 1215.2 | AC19: =AC7-AC17 -> -317.2 | AD19: =AD7-AD17 -> -124.3 | AE19: =AE7-AE17 -> 753.38 | AF19: =AF7-AF17 -> 473.06 | AG19: =AG7-AG17 -> 383.95 | AH19: =AH7-AH17 -> 690.27 | AI19: =AI7-AI17 -> 1274.5 | AJ19: =AJ7-AJ17 -> 3476.3
A20: Exceptional items, net | B20: INR Mn | C20: Company filings | D20: 0 | E20: 0 | F20: 0 | G20: 0 | H20: 0 | I20: 0 | J20: 0 | K20: 0 | L20: 0 | M20: 0 | N20: 0 | O20: 0 | P20: 0 | Q20: 0 | R20: 0 | S20: 0 | T20: 0 | U20: 10.4 | V20: 163.6 | W20: 0 | AC20: 0 | AD20: 0 | AE20: 0 | AF20: 0 | AG20: 0 | AH20: 0 | AI20: 0 | AJ20: 174
A21: Profit Before Tax | B21: INR Mn | D21: =D19-D20 -> 31.49 | E21: =E19-E20 -> 13.65 | F21: =F19-F20 -> 369.76 | G21: =G19-G20 -> 58.16 | H21: =H19-H20 -> 83.4 | I21: =I19-I20 -> 87.55 | J21: =J19-J20 -> 126.71 | K21: =K19-K20 -> 86.29 | ... W21: =W19-W20 -> 1215.2 | AC21: =AC19-AC20 -> -317.2 | AD21: =AD19-AD20 -> -124.3 | AE21: =AE19-AE20 -> 753.38 | AF21: =AF19-AF20 -> 473.06 | AG21: =AG19-AG20 -> 383.95 | AH21: =AH19-AH20 -> 690.27 | AI21: =AI19-AI20 -> 1274.5 | AJ21: =AJ19-AJ20 -> 3302.3
A23: Tax expense
A24: Current tax | B24: INR Mn | C24: Company filings | D24: 133.64 | E24: 3.66 | F24: 144.35 | G24: 141.28 | H24: 113.25 | I24: 215.91 | J24: 270.99 | K24: 260.96 | L24: 236.23 | M24: 215.86 | N24: 308.98 | O24: 306.28 | P24: 420.3 | Q24: 211.2 | R24: 319.9 | S24: -536.4 | T24: 177.3 | U24: 209.2 | V24: 279.2 | W24: 709.2 | AC24: 0 | AD24: 45.37 | AE24: 400.78 | AF24: 422.93 | AG24: 861.11 | AH24: 1067.35 | AI24: 415 | AJ24: 1374.9
A25: Current tax pertaining to earlier years | B25: INR Mn | C25: Company filings | D25: 0 | E25: 0 | F25: 0 | G25: 23.46 | H25: 0 | I25: 0 | J25: 0 | K25: 0 | L25: 0 | M25: 0 | N25: 0 | O25: 0 | P25: 0 | Q25: 0 | R25: 0 | S25: 0 | T25: 0 | U25: 0 | V25: 0 | W25: 0 | AC25: 0 | AD25: 0 | AE25: 0 | AF25: 23.46 | AG25: 0 | AH25: 0 | AI25: 0 | AJ25: 0
A26: Deferred tax expense/(credit) | B26: INR Mn | C26: Company filings | D26: -137.37 | E26: -1.73 | F26: -64.74 | G26: -124.27 | H26: -86.72 | I26: -184.91 | J26: -236.32 | K26: -217.42 | L26: -203.6 | M26: -176.18 | N26: -226.43 | O26: -208.03 | P26: -341.9 | Q26: -133 | R26: -144 | S26: 741.4 | T26: 15.1 | U26: 14.8 | V26: 139.6 | W26: -281.5 | AC26: -71.81 | AD26: -6.27 | AE26: -266.85 | AF26: -328.11 | AG26: -725.37 | AH26: -814.24 | AI26: 122.5 | AJ26: -112
A27: Deferred tax credit for unrecognised business loss (earlier years) | B27: INR Mn | C27: Company filings | D27: 0 | E27: 0 | F27: 0 | G27: -58.1 | H27: 0 | I27: 0 | J27: 0 | K27: 0 | L27: 0 | M27: 0 | N27: 0 | O27: 0 | P27: 0 | Q27: 0 | R27: 0 | S27: 0 | T27: 0 | U27: 0 | V27: 0 | W27: 0 | AC27: 0 | AD27: 0 | AE27: 0 | AF27: -58.1 | AG27: 0 | AH27: 0 | AI27: 0 | AJ27: 0
A28: Total Tax Expense/(Income) | B28: INR Mn | D28: =SUM(D24:D27) -> -3.73 | E28: =SUM(E24:E27) -> 1.93 | F28: =SUM(F24:F27) -> 79.61 | G28: =SUM(G24:G27) -> -17.63 | H28: =SUM(H24:H27) -> 26.53 | I28: =SUM(I24:I27) -> 31 | J28: =SUM(J24:J27) -> 34.67 | K28: =SUM(K24:K27) -> 43.54 | ... W28: =SUM(W24:W27) -> 427.7 | AC28: =SUM(AC24:AC27) -> -71.81 | AD28: =SUM(AD24:AD27) -> 39.1 | AE28: =SUM(AE24:AE27) -> 133.93 | AF28: =SUM(AF24:AF27) -> 60.18 | AG28: =SUM(AG24:AG27) -> 135.74 | AH28: =SUM(AH24:AH27) -> 253.11 | AI28: =SUM(AI24:AI27) -> 537.5 | AJ28: =SUM(AJ24:AJ27) -> 1262.9
A30: Net Profit After Tax | B30: INR Mn | D30: =D21-D28 -> 35.22 | E30: =E21-E28 -> 11.72 | F30: =F21-F28 -> 290.15 | G30: =G21-G28 -> 75.79 | H30: =H21-H28 -> 56.87 | I30: =I21-I28 -> 56.55 | J30: =J21-J28 -> 92.04 | K30: =K21-K28 -> 42.75 | ... W30: =W21-W28 -> 787.5 | AC30: =AC21-AC28 -> -245.39 | AD30: =AD21-AD28 -> -163.4 | AE30: =AE21-AE28 -> 619.45 | AF30: =AF21-AF28 -> 412.88 | AG30: =AG21-AG28 -> 248.21 | AH30: =AH21-AH28 -> 437.16 | AI30: =AI21-AI28 -> 737 | AJ30: =AJ21-AJ28 -> 2039.4
A31: Share in profit/(loss) of associate | B31: INR Mn | C31: Company filings | D31: 0 | E31: 0 | F31: 0 | G31: 0 | H31: -6.77 | I31: -4.64 | J31: -7.19 | K31: -20 | L31: -10.31 | M31: -14.89 | N31: -7.8 | O31: -6.66 | P31: -6 | Q31: -4.7 | R31: -5.6 | S31: 0 | T31: 0 | U31: 0 | V31: 0 | W31: 0 | AC31: 0 | AD31: 0 | AE31: 0 | AF31: 0 | AG31: -38.6 | AH31: -39.67 | AI31: -16.3 | AJ31: 0
A32: Net Profit/(Loss) for the Period | B32: INR Mn | D32: =D30+D31 -> 35.22 | E32: =E30+E31 -> 11.72 | F32: =F30+F31 -> 290.15 | G32: =G30+G31 -> 75.79 | H32: =H30+H31 -> 50.1 | I32: =I30+I31 -> 51.91 | J32: =J30+J31 -> 84.85 | K32: =K30+K31 -> 22.75 | ... W32: =W30+W31 -> 787.5 | AC32: =AC30+AC31 -> -245.39 | AD32: =AD30+AD31 -> -163.4 | AE32: =AE30+AE31 -> 619.45 | AF32: =AF30+AF31 -> 412.88 | AG32: =AG30+AG31 -> 209.61 | AH32: =AH30+AH31 -> 397.49 | AI32: =AI30+AI31 -> 720.7 | AJ32: =AJ30+AJ31 -> 2039.4
A34: Attributable to:
A35: Equity shareholders of parent | B35: INR Mn | C35: Company filings | D35: 34.15 | E35: 11.7 | F35: 279.3 | G35: 85.6 | H35: 45.5 | I35: 41.08 | J35: 81.93 | K35: 24.11 | L35: 33.03 | M35: 58.46 | N35: 161.86 | O35: 69.31 | P35: 96.4 | Q35: 100.4 | R35: 261.2 | S35: 202.8 | T35: 233.2 | U35: 344.3 | V35: 633.1 | W35: 783.8 | AC35: -245.18 | AD35: -166.09 | AE35: 618.48 | AF35: 410.75 | AG35: 192.62 | AH35: 322.65 | AI35: 660.8 | AJ35: 1994.4
A36: Non-controlling interests | B36: INR Mn | C36: Company filings | D36: 1.07 | E36: 0.02 | F36: 10.85 | G36: -9.81 | H36: 4.6 | I36: 10.83 | J36: 2.92 | K36: -1.36 | L36: 21.22 | M36: 19.54 | N36: 12.68 | O36: 21.4 | P36: 40 | Q36: 29.3 | R36: 2.9 | S36: -12.3 | T36: 11.5 | U36: -14.5 | V36: 44.3 | W36: 3.7 | AC36: -0.21 | AD36: 2.69 | AE36: 0.97 | AF36: 2.13 | AG36: 16.99 | AH36: 74.84 | AI36: 59.9 | AJ36: 45
A38: Total Other Comprehensive Income/(Loss), net of tax | B38: INR Mn | C38: Company filings | P38: 0 | Q38: -20.2 | R38: -1.3 | S38: -21.6 | T38: 1.2 | U38: 22.5 | V38: 4.8 | W38: 23.5 | AC38: 2.51 | AD38: 1.09 | AE38: -21.8 | AF38: 5.56 | AG38: 1.57 | AH38: 4.43 | AI38: -43.1 | AJ38: 52 | AL38: =SUM(D38:G38)-AF38 -> -5.56 | AM38: =SUM(H38:K38)-AG38 -> -1.57 | AN38: =SUM(L38:O38)-AH38 -> -4.43
A39: Total Comprehensive Income/(Loss) | B39: INR Mn | D39: =D32+D38 -> 35.22 | E39: =E32+E38 -> 11.72 | F39: =F32+F38 -> 290.15 | G39: =G32+G38 -> 75.79 | H39: =H32+H38 -> 50.1 | I39: =I32+I38 -> 51.91 | J39: =J32+J38 -> 84.85 | K39: =K32+K38 -> 22.75 | ... W39: =W32+W38 -> 811 | AC39: =AC32+AC38 -> -242.88 | AD39: =AD32+AD38 -> -162.31 | AE39: =AE32+AE38 -> 597.65 | AF39: =AF32+AF38 -> 418.44 | AG39: =AG32+AG38 -> 211.18 | AH39: =AH32+AH38 -> 401.92 | AI39: =AI32+AI38 -> 677.6 | AJ39: =AJ32+AJ38 -> 2091.4 | AL39: =SUM(D39:G39)-AF39 -> -5.56 | AM39: =SUM(H39:K39)-AG39 -> -1.57 | AN39: =SUM(L39:O39)-AH39 -> -4.42
A41: Basic EPS | B41: INR | C41: Company filings | D41: 0.08 | E41: 0.03 | F41: 0.6 | G41: 0.18 | H41: 0 | I41: 0.01 | J41: 0.03 | K41: 0.01 | L41: 0.02 | M41: 0.02 | N41: 0.06 | O41: 0.02 | P41: 0.03 | Q41: 0.04 | R41: 0.09 | S41: 0.07 | T41: 0.08 | U41: 0.12 | V41: 0.22 | W41: 0.27 | AC41: -17.7 | AD41: -11.63 | AE41: 41.66 | AF41: 0.88 | AG41: 0.07 | AH41: 0.11 | AI41: 0.23 | AJ41: 0.7
A42: Diluted EPS | B42: INR | C42: Company filings | D42: 0.07 | E42: 0.03 | F42: 0.6 | G42: 0.18 | H42: 0 | I42: 0.01 | J42: 0.03 | K42: 0.01 | L42: 0.02 | M42: 0.02 | N42: 0.06 | O42: 0.02 | P42: 0.03 | Q42: 0.04 | R42: 0.09 | S42: 0.07 | T42: 0.08 | U42: 0.12 | V42: 0.22 | W42: 0.27 | AC42: -17.7 | AD42: -11.63 | AE42: 40.07 | AF42: 0.87 | AG42: 0.07 | AH42: 0.11 | AI42: 0.23 | AJ42: 0.7
A43: Note: FY19-FY21 EPS computed on face value of Rs 10/share (Restated Ind AS statements, RHP); face value changed to Re 1/share from FY22 following share sub-division. Not directly comparable across the break.
A46: BALANCE SHEET (CONSOLIDATED)
A47: ASSETS
A48: Non-current assets
A49: Property, plant and equipment | B49: INR Mn | C49: Company filings | G49: 1244.42 | I49: 1713.47 | K49: 2313.46 | M49: 2315.23 | O49: 2357.72 | Q49: 2351.5 | S49: 2717.2 | U49: 2712.6 | W49: 2999.7 | AC49: 429.05 | AD49: 701.49 | AE49: 686.52 | AF49: 1244.42 | AG49: 2313.46 | AH49: 2357.72 | AI49: 2717.2 | AJ49: 2999.7
...

Sheet Raw Data - Ops KPIs
A3: All figures in INR Mn unless stated otherwise.
A5: Metric | B5: Unit | C5: Source - Deck section | D5: Q1FY22 | E5: Q2FY22 | F5: Q3FY22 | G5: Q4FY22 | H5: Q1FY23 | I5: Q2FY23 | J5: Q3FY23 | K5: Q4FY23 | L5: Q1FY24 | M5: Q2FY24 | N5: Q3FY24 | O5: Q4FY24 | P5: Q1FY25 | Q5: Q2FY25 | R5: Q3FY25 | S5: Q4FY25 | T5: Q1FY26 | U5: Q2FY26 | V5: Q3FY26 | W5: Q4FY26 | X5: Q1FY27 | Y5: Q2FY27 | Z5: Q3FY27 | AA5: Q4FY27 | AF5: FY22 | AG5: FY23 | AH5: FY24 | AI5: FY25 | AJ5: FY26
A6: Consolidated Operating KPIs
A7: Number of visits | B7: mn | C7: One Nykaa Highlights | D7: 312.4 | E7: 335 | F7: 347 | G7: 328 | H7: 354 | I7: 372 | J7: 403 | K7: 369 | L7: 395 | M7: 430 | N7: 468 | O7: 447 | AF7: =IF(COUNT(D7:G7)=0,"",SUM(D7:G7)) -> 1322.4 | AG7: =IF(COUNT(H7:K7)=0,"",SUM(H7:K7)) -> 1498 | AH7: =IF(COUNT(L7:O7)=0,"",SUM(L7:O7)) -> 1740 | AI7: =IF(COUNT(P7:S7)=0,"",SUM(P7:S7)) | AJ7: =IF(COUNT(T7:W7)=0,"",SUM(T7:W7))
A8: Annual transacting customers | B8: mn | C8: One Nykaa Highlights | D8: 7.7 | E8: 8.6 | F8: 9.4 | G8: 10.2 | H8: 11 | I8: 11.7 | J8: 12.5 | K8: 13 | L8: 13.5 | M8: 14 | N8: 14.6 | O8: 15.4 | AF8: =IF(G8="","",G8) -> 10.2 | AG8: =IF(K8="","",K8) -> 13 | AH8: =IF(O8="","",O8) -> 15.4 | AI8: =IF(S8="","",S8) | AJ8: =IF(W8="","",W8)
A9: YoY growth | B9: % | H9: =IFERROR(H8/D8-1,"") -> 0.42857143 | I9: =IFERROR(I8/E8-1,"") -> 0.36046512 | J9: =IFERROR(J8/F8-1,"") -> 0.32978723 | K9: =IFERROR(K8/G8-1,"") -> 0.2745098 | L9: =IFERROR(L8/H8-1,"") -> 0.22727273 | M9: =IFERROR(M8/I8-1,"") -> 0.1965812 | N9: =IFERROR(N8/J8-1,"") -> 0.168 | O9: =IFERROR(O8/K8-1,"") -> 0.18461538 | ... AA9: =IFERROR(AA8/W8-1,"") | AF9: =IFERROR(AF8/AE8-1,"") | AG9: =IFERROR(AG8/AF8-1,"") -> 0.2745098 | AH9: =IFERROR(AH8/AG8-1,"") -> 0.18461538 | AI9: =IFERROR(AI8/AH8-1,"") | AJ9: =IFERROR(AJ8/AI8-1,"")
A10: Number of orders | B10: mn | C10: One Nykaa Highlights | D10: 7 | E10: 7.4 | F10: 9 | G10: 8.7 | H10: 9.9 | I10: 10.1 | J10: 11.6 | K10: 10.6 | L10: 11.4 | M10: 12.2 | N10: 13.7 | O10: 13.4 | AF10: =IF(COUNT(D10:G10)=0,"",SUM(D10:G10)) -> 32.1 | AG10: =IF(COUNT(H10:K10)=0,"",SUM(H10:K10)) -> 42.2 | AH10: =IF(COUNT(L10:O10)=0,"",SUM(L10:O10)) -> 50.7 | AI10: =IF(COUNT(P10:S10)=0,"",SUM(P10:S10)) | AJ10: =IF(COUNT(T10:W10)=0,"",SUM(T10:W10))
A11: Total GMV | B11: Rs Mn | C11: One Nykaa Highlights | D11: 14696 | E11: 16229 | F11: 20428 | G11: 17979 | H11: 21588 | I11: 23457 | J11: 27965 | K11: 24454 | L11: 26678 | M11: 29435 | N11: 36195 | O11: 32163 | P11: 33209 | Q11: 36525 | R11: 45279 | S11: 41020 | T11: 41820 | U11: 47440 | V11: 57950 | W11: 52410 | AF11: =IF(COUNT(D11:G11)=0,"",SUM(D11:G11)) -> 69332 | AG11: =IF(COUNT(H11:K11)=0,"",SUM(H11:K11)) -> 97464 | AH11: =IF(COUNT(L11:O11)=0,"",SUM(L11:O11)) -> 124471 | AI11: =IF(COUNT(P11:S11)=0,"",SUM(P11:S11)) -> 156033 | AJ11: =IF(COUNT(T11:W11)=0,"",SUM(T11:W11)) -> 199620
A12: YoY growth | B12: % | H12: =IFERROR(H11/D11-1,"") -> 0.46897115 | I12: =IFERROR(I11/E11-1,"") -> 0.44537556 | J12: =IFERROR(J11/F11-1,"") -> 0.36895438 | K12: =IFERROR(K11/G11-1,"") -> 0.36014239 | L12: =IFERROR(L11/H11-1,"") -> 0.23577914 | M12: =IFERROR(M11/I11-1,"") -> 0.2548493 | N12: =IFERROR(N11/J11-1,"") -> 0.29429644 | O12: =IFERROR(O11/K11-1,"") -> 0.31524495 | ... AA12: =IFERROR(AA11/W11-1,"") -> -1 | AF12: =IFERROR(AF11/AE11-1,"") | AG12: =IFERROR(AG11/AF11-1,"") -> 0.4057578 | AH12: =IFERROR(AH11/AG11-1,"") -> 0.27709718 | AI12: =IFERROR(AI11/AH11-1,"") -> 0.2535691 | AJ12: =IFERROR(AJ11/AI11-1,"") -> 0.27934475
A13: QoQ growth | B13: % | E13: =IFERROR(E11/D11-1,"") -> 0.1043141 | F13: =IFERROR(F11/E11-1,"") -> 0.25873436 | G13: =IFERROR(G11/F11-1,"") -> -0.11988447 | H13: =IFERROR(H11/G11-1,"") -> 0.20073419 | I13: =IFERROR(I11/H11-1,"") -> 0.086575875 | J13: =IFERROR(J11/I11-1,"") -> 0.19218144 | K13: =IFERROR(K11/J11-1,"") -> -0.12554979 | L13: =IFERROR(L11/K11-1,"") -> 0.090946266 | ... AA13: =IFERROR(AA11/Z11-1,"")
A14: Total NSV | B14: Rs Mn | C14: One Nykaa Highlights | D14: 8050 | E14: 8688 | F14: 10729 | G14: 9650 | H14: 11272 | I14: 12049 | J14: 14401 | K14: 12904 | L14: 14205 | M14: 14982 | N14: 17866 | O14: 16489 | P14: 17183 | Q14: 18432 | R14: 22190 | S14: 20430 | T14: 21370 | U14: 23400 | V14: 28440 | W14: 26780 | AF14: =IF(COUNT(D14:G14)=0,"",SUM(D14:G14)) -> 37117 | AG14: =IF(COUNT(H14:K14)=0,"",SUM(H14:K14)) -> 50626 | AH14: =IF(COUNT(L14:O14)=0,"",SUM(L14:O14)) -> 63542 | AI14: =IF(COUNT(P14:S14)=0,"",SUM(P14:S14)) -> 78235 | AJ14: =IF(COUNT(T14:W14)=0,"",SUM(T14:W14)) -> 99990
A15: NSV / GMV | B15: % | D15: =IFERROR(D14/D11,"") -> 0.5477681 | E15: =IFERROR(E14/E11,"") -> 0.53533798 | F15: =IFERROR(F14/F11,"") -> 0.5252105 | G15: =IFERROR(G14/G11,"") -> 0.5367373 | H15: =IFERROR(H14/H11,"") -> 0.52214193 | I15: =IFERROR(I14/I11,"") -> 0.5136633 | J15: =IFERROR(J14/J11,"") -> 0.51496513 | K15: =IFERROR(K14/K11,"") -> 0.52768463 | ... AA15: =IFERROR(AA14/AA11,"") | AF15: =IFERROR(AF14/AF11,"") -> 0.53535164 | AG15: =IFERROR(AG14/AG11,"") -> 0.51943282 | AH15: =IFERROR(AH14/AH11,"") -> 0.51049642 | AI15: =IFERROR(AI14/AI11,"") -> 0.50140034 | AJ15: =IFERROR(AJ14/AJ11,"") -> 0.50090171
A16: Total Revenue | B16: Rs Mn | C16: One Nykaa Highlights / Financial Performance | D16: 8169.91 | E16: 8852.64 | F16: 10983.6 | G16: 9733.2 | H16: 11484.21 | I16: 12308.29 | J16: 14628.26 | K16: 13017.24 | L16: 14218.24 | M16: 15070.24 | N16: 17887.98 | O16: 16679.8 | P16: 17461.1 | Q16: 18747.4 | R16: 22672.1 | S16: 20617.6 | T16: 21549.4 | U16: 23459.8 | V16: 28732.6 | W16: 26480 | AF16: =IF(COUNT(D16:G16)=0,"",SUM(D16:G16)) -> 37739.35 | AG16: =IF(COUNT(H16:K16)=0,"",SUM(H16:K16)) -> 51438 | AH16: =IF(COUNT(L16:O16)=0,"",SUM(L16:O16)) -> 63856.26 | AI16: =IF(COUNT(P16:S16)=0,"",SUM(P16:S16)) -> 79498.2 | AJ16: =IF(COUNT(T16:W16)=0,"",SUM(T16:W16)) -> 100221.8
A17: YoY growth | B17: % | H17: =IFERROR(H16/D16-1,"") -> 0.40567154 | I17: =IFERROR(I16/E16-1,"") -> 0.39035248 | J17: =IFERROR(J16/F16-1,"") -> 0.33182745 | K17: =IFERROR(K16/G16-1,"") -> 0.33740599 | L17: =IFERROR(L16/H16-1,"") -> 0.23806862 | M17: =IFERROR(M16/I16-1,"") -> 0.22439754 | N17: =IFERROR(N16/J16-1,"") -> 0.22283717 | O17: =IFERROR(O16/K16-1,"") -> 0.28136225 | ... AA17: =IFERROR(AA16/W16-1,"") -> -1 | AF17: =IFERROR(AF16/AE16-1,"") | AG17: =IFERROR(AG16/AF16-1,"") -> 0.36298055 | AH17: =IFERROR(AH16/AG16-1,"") -> 0.24142191 | AI17: =IFERROR(AI16/AH16-1,"") -> 0.24495547 | AJ17: =IFERROR(AJ16/AI16-1,"") -> 0.26068012
A18: Revenue / NSV | B18: % | D18: =IFERROR(D16/D14,"") -> 1.0148957 | E18: =IFERROR(E16/E14,"") -> 1.0189503 | F18: =IFERROR(F16/F14,"") -> 1.0237301 | G18: =IFERROR(G16/G14,"") -> 1.0086218 | H18: =IFERROR(H16/H14,"") -> 1.0188263 | I18: =IFERROR(I16/I14,"") -> 1.0215196 | J18: =IFERROR(J16/J14,"") -> 1.0157808 | K18: =IFERROR(K16/K14,"") -> 1.0087756 | ... AA18: =IFERROR(AA16/AA14,"") | AF18: =IFERROR(AF16/AF14,"") -> 1.0167672 | AG18: =IFERROR(AG16/AG14,"") -> 1.0160392 | AH18: =IFERROR(AH16/AH14,"") -> 1.0049457 | AI18: =IFERROR(AI16/AI14,"") -> 1.0161462 | AJ18: =IFERROR(AJ16/AJ14,"") -> 1.0023182
A19: Gross profit | B19: Rs Mn | C19: Financial Performance (Total column) | D19: 3316.59 | E19: 3782.42 | F19: 5087.58 | G19: 4252.61 | H19: 5098.79 | I19: 5577.38 | J19: 6346.7 | K19: 5758.32 | L19: 6186.25 | M19: 6496.24 | N19: 7607.48 | O19: 7102.43 | P19: 7559.8 | Q19: 8210.2 | R19: 9911.4 | S19: 9090.2 | T19: 9615.1 | U19: 10535.4 | V19: 12974.8 | W19: 12030 | AF19: =IF(COUNT(D19:G19)=0,"",SUM(D19:G19)) -> 16439.2 | AG19: =IF(COUNT(H19:K19)=0,"",SUM(H19:K19)) -> 22781.19 | AH19: =IF(COUNT(L19:O19)=0,"",SUM(L19:O19)) -> 27392.4 | AI19: =IF(COUNT(P19:S19)=0,"",SUM(P19:S19)) -> 34771.6 | AJ19: =IF(COUNT(T19:W19)=0,"",SUM(T19:W19)) -> 45155.3
A20: Gross margin (% of NSV) | B20: % | D20: =IFERROR(D19/D14,"") -> 0.41199876 | E20: =IFERROR(E19/E14,"") -> 0.43536142 | F20: =IFERROR(F19/F14,"") -> 0.47418958 | G20: =IFERROR(G19/G14,"") -> 0.44068497 | H20: =IFERROR(H19/H14,"") -> 0.4523412 | I20: =IFERROR(I19/I14,"") -> 0.46289153 | J20: =IFERROR(J19/J14,"") -> 0.44071245 | K20: =IFERROR(K19/K14,"") -> 0.44624303 | ... AA20: =IFERROR(AA19/AA14,"") | AF20: =IFERROR(AF19/AF14,"") -> 0.44290217 | AG20: =IFERROR(AG19/AG14,"") -> 0.44998993 | AH20: =IFERROR(AH19/AH14,"") -> 0.43109125 | AI20: =IFERROR(AI19/AI14,"") -> 0.44445069 | AJ20: =IFERROR(AJ19/AJ14,"") -> 0.45159816
A21: Fulfilment cost | B21: Rs Mn | C21: Financial Performance (Total column) | D21: 934 | E21: 910 | F21: 1162 | G21: 949 | H21: 1294 | I21: 1454 | J21: 1288 | K21: 1286 | L21: 1357 | M21: 1459 | N21: 1718 | O21: 1550 | P21: 1667 | Q21: 1748 | R21: 2090 | S21: 1920 | T21: 2030 | U21: 2270 | V21: 2690 | W21: 2600 | AF21: =IF(COUNT(D21:G21)=0,"",SUM(D21:G21)) -> 3955 | AG21: =IF(COUNT(H21:K21)=0,"",SUM(H21:K21)) -> 5322 | AH21: =IF(COUNT(L21:O21)=0,"",SUM(L21:O21)) -> 6084 | AI21: =IF(COUNT(P21:S21)=0,"",SUM(P21:S21)) -> 7425 | AJ21: =IF(COUNT(T21:W21)=0,"",SUM(T21:W21)) -> 9590
A22: Marketing & S&D expense (combined) | B22: Rs Mn | C22: Financial Performance (Total column) | D22: 1099 | E22: 1521 | F22: 1846 | G22: 1561 | H22: 1524 | I22: 1635 | J22: 1982 | K22: 1670 | L22: 1919 | M22: 2036 | N22: 2558 | O22: 2361 | P22: 2483 | Q22: 2767 | R22: 3620 | S22: 3160 | T22: 3180 | U22: 3560 | V22: 4380 | W22: 3740 | AF22: =IF(COUNT(D22:G22)=0,"",SUM(D22:G22)) -> 6027 | AG22: =IF(COUNT(H22:K22)=0,"",SUM(H22:K22)) -> 6811 | AH22: =IF(COUNT(L22:O22)=0,"",SUM(L22:O22)) -> 8874 | AI22: =IF(COUNT(P22:S22)=0,"",SUM(P22:S22)) -> 12030 | AJ22: =IF(COUNT(T22:W22)=0,"",SUM(T22:W22)) -> 14860
A23: Contribution profit | B23: Rs Mn | D23: =IF(OR(ISBLANK(D19),ISBLANK(D21),ISBLANK(D22)),"",IFERROR(D19-D21-D22,"")) -> 1283.59 | E23: =IF(OR(ISBLANK(E19),ISBLANK(E21),ISBLANK(E22)),"",IFERROR(E19-E21-E22,"")) -> 1351.42 | F23: =IF(OR(ISBLANK(F19),ISBLANK(F21),ISBLANK(F22)),"",IFERROR(F19-F21-F22,"")) -> 2079.58 | G23: =IF(OR(ISBLANK(G19),ISBLANK(G21),ISBLANK(G22)),"",IFERROR(G19-G21-G22,"")) -> 1742.61 | H23: =IF(OR(ISBLANK(H19),ISBLANK(H21),ISBLANK(H22)),"",IFERROR(H19-H21-H22,"")) -> 2280.79 | I23: =IF(OR(ISBLANK(I19),ISBLANK(I21),ISBLANK(I22)),"",IFERROR(I19-I21-I22,"")) -> 2488.38 | J23: =IF(OR(ISBLANK(J19),ISBLANK(J21),ISBLANK(J22)),"",IFERROR(J19-J21-J22,"")) -> 3076.7 | K23: =IF(OR(ISBLANK(K19),ISBLANK(K21),ISBLANK(K22)),"",IFERROR(K19-K21-K22,"")) -> 2802.32 | ... AA23: =IF(OR(ISBLANK(AA19),ISBLANK(AA21),ISBLANK(AA22)),"",IFERROR(AA19-AA21-AA22,"")) | AF23: =IF(OR(ISBLANK(AF19),ISBLANK(AF21),ISBLANK(AF22)),"",IFERROR(AF19-AF21-AF22,"")) -> 6457.2 | AG23: =IF(OR(ISBLANK(AG19),ISBLANK(AG21),ISBLANK(AG22)),"",IFERROR(AG19-AG21-AG22,"")) -> 10648.19 | AH23: =IF(OR(ISBLANK(AH19),ISBLANK(AH21),ISBLANK(AH22)),"",IFERROR(AH19-AH21-AH22,"")) -> 12434.4 | AI23: =IF(OR(ISBLANK(AI19),ISBLANK(AI21),ISBLANK(AI22)),"",IFERROR(AI19-AI21-AI22,"")) -> 15316.6 | AJ23: =IF(OR(ISBLANK(AJ19),ISBLANK(AJ21),ISBLANK(AJ22)),"",IFERROR(AJ19-AJ21-AJ22,"")) -> 20705.3
A24: Contribution margin (% of NSV) | B24: % | D24: =IFERROR(D23/D14,"") -> 0.15945217 | E24: =IFERROR(E23/E14,"") -> 0.15555018 | F24: =IFERROR(F23/F14,"") -> 0.19382794 | G24: =IFERROR(G23/G14,"") -> 0.18058135 | H24: =IFERROR(H23/H14,"") -> 0.2023412 | I24: =IFERROR(I23/I14,"") -> 0.2065217 | J24: =IFERROR(J23/J14,"") -> 0.21364489 | K24: =IFERROR(K23/K14,"") -> 0.21716677 | ... AA24: =IFERROR(AA23/AA14,"") | AF24: =IFERROR(AF23/AF14,"") -> 0.1739688 | AG24: =IFERROR(AG23/AG14,"") -> 0.21033046 | AH24: =IFERROR(AH23/AH14,"") -> 0.19568789 | AI24: =IFERROR(AI23/AI14,"") -> 0.19577683 | AJ24: =IFERROR(AJ23/AJ14,"") -> 0.20707371
A25: Other expenses (G&A + employee) | B25: Rs Mn | C25: Financial Performance (Total column) | D25: 1014.15 | E25: 1063.18 | F25: 1735.81 | G25: 1357 | H25: 1820.27 | I25: 1877.01 | J25: 2295.1 | K25: 2095.38 | L25: 2175.59 | M25: 2194.95 | N25: 2343.74 | O25: 2258.61 | P25: 2448.6 | Q25: 2658.6 | R25: 2793.6 | S25: 2676.7 | T25: 2898.3 | U25: 2995.9 | V25: 3387.2 | W25: 3470 | AF25: =IF(COUNT(D25:G25)=0,"",SUM(D25:G25)) -> 5170.14 | AG25: =IF(COUNT(H25:K25)=0,"",SUM(H25:K25)) -> 8087.76 | AH25: =IF(COUNT(L25:O25)=0,"",SUM(L25:O25)) -> 8972.89 | AI25: =IF(COUNT(P25:S25)=0,"",SUM(P25:S25)) -> 10577.5 | AJ25: =IF(COUNT(T25:W25)=0,"",SUM(T25:W25)) -> 12751.4
A26: EBITDA | B26: Rs Mn | D26: =IF(OR(ISBLANK(D23),ISBLANK(D25)),"",IFERROR(D23-D25,"")) -> 269.44 | E26: =IF(OR(ISBLANK(E23),ISBLANK(E25)),"",IFERROR(E23-E25,"")) -> 288.24 | F26: =IF(OR(ISBLANK(F23),ISBLANK(F25)),"",IFERROR(F23-F25,"")) -> 343.77 | G26: =IF(OR(ISBLANK(G23),ISBLANK(G25)),"",IFERROR(G23-G25,"")) -> 385.61 | H26: =IF(OR(ISBLANK(H23),ISBLANK(H25)),"",IFERROR(H23-H25,"")) -> 460.52 | I26: =IF(OR(ISBLANK(I23),ISBLANK(I25)),"",IFERROR(I23-I25,"")) -> 611.37 | J26: =IF(OR(ISBLANK(J23),ISBLANK(J25)),"",IFERROR(J23-J25,"")) -> 781.6 | K26: =IF(OR(ISBLANK(K23),ISBLANK(K25)),"",IFERROR(K23-K25,"")) -> 706.94 | ... AA26: =IF(OR(ISBLANK(AA23),ISBLANK(AA25)),"",IFERROR(AA23-AA25,"")) | AF26: =IF(OR(ISBLANK(AF23),ISBLANK(AF25)),"",IFERROR(AF23-AF25,"")) -> 1287.06 | AG26: =IF(OR(ISBLANK(AG23),ISBLANK(AG25)),"",IFERROR(AG23-AG25,"")) -> 2560.43 | AH26: =IF(OR(ISBLANK(AH23),ISBLANK(AH25)),"",IFERROR(AH23-AH25,"")) -> 3461.51 | AI26: =IF(OR(ISBLANK(AI23),ISBLANK(AI25)),"",IFERROR(AI23-AI25,"")) -> 4739.1 | AJ26: =IF(OR(ISBLANK(AJ23),ISBLANK(AJ25)),"",IFERROR(AJ23-AJ25,"")) -> 7953.9
A27: EBITDA margin (% of NSV) | B27: % | D27: =IFERROR(D26/D14,"") -> 0.033470807 | E27: =IFERROR(E26/E14,"") -> 0.033176796 | F27: =IFERROR(F26/F14,"") -> 0.032041197 | G27: =IFERROR(G26/G14,"") -> 0.039959585 | H27: =IFERROR(H26/H14,"") -> 0.040855216 | I27: =IFERROR(I26/I14,"") -> 0.05074031 | J27: =IFERROR(J26/J14,"") -> 0.054274009 | K27: =IFERROR(K26/K14,"") -> 0.054784563 | ... AA27: =IFERROR(AA26/AA14,"") | AF27: =IFERROR(AF26/AF14,"") -> 0.034675755 | AG27: =IFERROR(AG26/AG14,"") -> 0.050575396 | AH27: =IFERROR(AH26/AH14,"") -> 0.054475937 | AI27: =IFERROR(AI26/AI14,"") -> 0.06057519 | AJ27: =IFERROR(AJ26/AJ14,"") -> 0.079546955
A29: Beauty (incl. SuperStore) - Omnichannel Retail
A30: Definition: BPC (online + offline) + Superstore by Nykaa + Nykaa Man Grooming + House of Nykaa owned brands
A31: Number of visits | B31: mn | C31: Beauty Omnichannel Retail | D31: 205 | E31: 211 | F31: 221 | G31: 204 | H31: 222 | I31: 234 | J31: 250 | K31: 231 | L31: 269 | M31: 287 | N31: 311 | O31: 303 | P31: 330 | Q31: 357 | R31: 401 | S31: 393 | T31: 411 | U31: 450 | V31: 538 | W31: =AJ31-SUM(T31:V31) -> 495 | AF31: =IF(COUNT(D31:G31)=0,"",SUM(D31:G31)) -> 841 | AG31: =IF(COUNT(H31:K31)=0,"",SUM(H31:K31)) -> 937 | AH31: =IF(COUNT(L31:O31)=0,"",SUM(L31:O31)) -> 1170 | AI31: =IF(COUNT(P31:S31)=0,"",SUM(P31:S31)) -> 1481 | AJ31: 1894
A32: Monthly average unique visitors | B32: mn | C32: Beauty Omnichannel Retail | D32: 17.3 | E32: 19.4 | F32: 19.8 | G32: 18.5 | H32: 21.8 | I32: 22.1 | J32: 24.2 | K32: 22.5 | L32: 27.3 | M32: 26.8 | N32: 29.6 | O32: 31.9 | P32: 32.6 | Q32: 34.2 | R32: 38.1 | S32: 38 | T32: 38.8 | U32: 41.6 | V32: 50.7 | AF32: =IFERROR(AVERAGE(D32:G32),"") -> 18.75 | AG32: =IFERROR(AVERAGE(H32:K32),"") -> 22.65 | AH32: 30.2 | AI32: =IFERROR(AVERAGE(P32:S32),"") -> 35.725 | AJ32: 44.7
A33: Conversion - orders/visits | B33: % | D33: =IFERROR(D37/D31,"") -> 0.028292683 | E33: =IFERROR(E37/E31,"") -> 0.028436019 | F33: =IFERROR(F37/F31,"") -> 0.033936652 | G33: =IFERROR(G37/G31,"") -> 0.035294118 | H33: =IFERROR(H37/H31,"") -> 0.036486486 | I33: =IFERROR(I37/I31,"") -> 0.035897436 | J33: =IFERROR(J37/J31,"") -> 0.038 | K33: =IFERROR(K37/K31,"") -> 0.038095238 | ... AA33: =IFERROR(AA37/AA31,"") | AF33: =IFERROR(AF37/AF31,"") -> 0.031510107 | AG33: =IFERROR(AG37/AG31,"") -> 0.037139808 | AH33: =IFERROR(AH37/AH31,"") -> 0.037350427 | AI33: =IFERROR(AI37/AI31,"") -> 0.03679946 | AJ33: =IFERROR(AJ37/AJ31,"") -> 0.034741288
A34: Conversion - transacting customers/visits | B34: % | D34: =IFERROR(D35/D31,"") -> 0.031707317 | E34: =IFERROR(E35/E31,"") -> 0.033175355 | F34: =IFERROR(F35/F31,"") -> 0.033936652 | G34: =IFERROR(G35/G31,"") -> 0.039215686 | H34: =IFERROR(H35/H31,"") -> 0.038738739 | I34: =IFERROR(I35/I31,"") -> 0.038888889 | J34: =IFERROR(J35/J31,"") -> 0.0384 | K34: =IFERROR(K35/K31,"") -> 0.043290043 | ... AA34: =IFERROR(AA35/AA31,"") | AF34: =IFERROR(AF35/AF31,"") -> 0.0095124851 | AG34: =IFERROR(AG35/AG31,"") -> 0.010672359 | AH34: =IFERROR(AH35/AH31,"") -> 0.010598291 | AI34: =IFERROR(AI35/AI31,"") -> 0.010668467 | AJ34: =IFERROR(AJ35/AJ31,"") -> 0.010401267
A35: Annual transacting customers | B35: mn | C35: Beauty Omnichannel Retail | D35: 6.5 | E35: 7 | F35: 7.5 | G35: 8 | H35: 8.6 | I35: 9.1 | J35: 9.6 | K35: 10 | L35: 10.9 | M35: 10.7 | N35: 11.7 | O35: 12.4 | P35: 13.1 | Q35: 13.7 | R35: 14.8 | S35: 15.8 | T35: 16.5 | U35: 17.5 | V35: 18.7 | W35: 19.7 | AF35: =IF(G35="","",G35) -> 8 | AG35: =IF(K35="","",K35) -> 10 | AH35: =IF(O35="","",O35) -> 12.4 | AI35: =IF(S35="","",S35) -> 15.8 | AJ35: =IF(W35="","",W35) -> 19.7
A36: Average order frequency | B36: x | D36: =IFERROR(D37*4/D35,"") -> 3.5692308 | E36: =IFERROR(E37*4/E35,"") -> 3.4285714 | F36: =IFERROR(F37*4/F35,"") -> 4 | G36: =IFERROR(G37*4/G35,"") -> 3.6 | H36: =IFERROR(H37*4/H35,"") -> 3.7674419 | I36: =IFERROR(I37*4/I35,"") -> 3.6923077 | J36: =IFERROR(J37*4/J35,"") -> 3.9583333 | K36: =IFERROR(K37*4/K35,"") -> 3.52 | ... AA36: =IFERROR(AA37*4/AA35,"") | AF36: =IFERROR(AF37*4/AF35,"") -> 13.25 | AG36: =IFERROR(AG37*4/AG35,"") -> 13.92 | AH36: =IFERROR(AH37*4/AH35,"") -> 14.096774 | AI36: =IFERROR(AI37*4/AI35,"") -> 13.797468 | AJ36: =IFERROR(AJ37*4/AJ35,"") -> 13.360406
A37: Number of orders | B37: mn | C37: Beauty Omnichannel Retail | D37: 5.8 | E37: 6 | F37: 7.5 | G37: 7.2 | H37: 8.1 | I37: 8.4 | J37: 9.5 | K37: 8.8 | L37: 9.9 | M37: 10.5 | N37: 11.6 | O37: 11.7 | P37: 12.4 | Q37: 12.9 | R37: 15 | S37: 14.2 | T37: 14.5 | U37: 15.7 | V37: 18.1 | W37: =AJ37-SUM(T37:V37) -> 17.5 | AF37: =IF(COUNT(D37:G37)=0,"",SUM(D37:G37)) -> 26.5 | AG37: =IF(COUNT(H37:K37)=0,"",SUM(H37:K37)) -> 34.8 | AH37: =IF(COUNT(L37:O37)=0,"",SUM(L37:O37)) -> 43.7 | AI37: =IF(COUNT(P37:S37)=0,"",SUM(P37:S37)) -> 54.5 | AJ37: 65.8
A38: Average order value (computed: GMV / Orders) | B38: Rs | D38: =IFERROR(D40/D37,"") -> 0 | E38: =IFERROR(E40/E37,"") -> 0 | F38: =IFERROR(F40/F37,"") -> 0 | G38: =IFERROR(G40/G37,"") -> 0 | H38: =IFERROR(H40/H37,"") -> 0 | I38: =IFERROR(I40/I37,"") -> 0 | J38: =IFERROR(J40/J37,"") -> 0 | K38: =IFERROR(K40/K37,"") -> 0 | ... AA38: =IFERROR(AA40/AA37,"") | AF38: =IFERROR(AF40/AF37,"") | AG38: =IFERROR(AG40/AG37,"") | AH38: =IFERROR(AH40/AH37,"") -> 2072.151 | AI38: =IFERROR(AI40/AI37,"") -> 2160.3853 | AJ38: =IFERROR(AJ40/AJ37,"") -> 2272.4924
A39: Average order value (as reported) | B39: Rs | C39: Link: row 148 (Beauty AOV reconciliation) | D39: =IF(D148="","",IFERROR(D148,"")) -> 1832 | E39: =IF(E148="","",IFERROR(E148,"")) -> 1910 | F39: =IF(F148="","",IFERROR(F148,"")) -> 1967 | G39: =IF(G148="","",IFERROR(G148,"")) -> 1716 | H39: =IF(H148="","",IFERROR(H148,"")) -> 1780 | I39: =IF(I148="","",IFERROR(I148,"")) -> 1872 | J39: =IF(J148="","",IFERROR(J148,"")) -> 1958 | K39: =IF(K148="","",IFERROR(K148,"")) -> 1803 | ... V39: =IF(V148="","",IFERROR(V148,"")) -> 2173 | AF39: =IF(AF148="","",IFERROR(AF148,"")) -> 1857 | AG39: =IF(AG148="","",IFERROR(AG148,"")) -> 1857 | AH39: =IF(AH148="","",IFERROR(AH148,"")) -> 1985 | AI39: =IF(AI148="","",IFERROR(AI148,"")) -> 2021 | AJ39: =IF(AJ148="","",IFERROR(AJ148,"")) -> 2068
A40: GMV | B40: Rs Mn | C40: Beauty Omnichannel Retail | L40: 19908 | M40: 21559 | N40: 25696 | O40: 23390 | P40: 25429 | Q40: 27833 | R40: 33899 | S40: 30580 | T40: 32080 | U40: 35510 | V40: 43020 | W40: 38920 | AF40: =IF(COUNT(D40:G40)=0,"",SUM(D40:G40)) | AG40: =IF(COUNT(H40:K40)=0,"",SUM(H40:K40)) | AH40: =IF(COUNT(L40:O40)=0,"",SUM(L40:O40)) -> 90553 | AI40: =IF(COUNT(P40:S40)=0,"",SUM(P40:S40)) -> 117741 | AJ40: =IF(COUNT(T40:W40)=0,"",SUM(T40:W40)) -> 149530
A41: YoY growth | B41: % | H41: =IFERROR(H40/D40-1,"") | I41: =IFERROR(I40/E40-1,"") | J41: =IFERROR(J40/F40-1,"") | K41: =IFERROR(K40/G40-1,"") | L41: =IFERROR(L40/H40-1,"") | M41: =IFERROR(M40/I40-1,"") | N41: =IFERROR(N40/J40-1,"") | O41: =IFERROR(O40/K40-1,"") | ... AA41: =IFERROR(AA40/W40-1,"") -> -1 | AF41: =IFERROR(AF40/AE40-1,"") | AG41: =IFERROR(AG40/AF40-1,"") | AH41: =IFERROR(AH40/AG40-1,"") | AI41: =IFERROR(AI40/AH40-1,"") -> 0.30024406 | AJ41: =IFERROR(AJ40/AI40-1,"") -> 0.26999091
A42: QoQ growth | B42: % | E42: =IFERROR(E40/D40-1,"") | F42: =IFERROR(F40/E40-1,"") | G42: =IFERROR(G40/F40-1,"") | H42: =IFERROR(H40/G40-1,"") | I42: =IFERROR(I40/H40-1,"") | J42: =IFERROR(J40/I40-1,"") | K42: =IFERROR(K40/J40-1,"") | L42: =IFERROR(L40/K40-1,"") | ... AA42: =IFERROR(AA40/Z40-1,"")
